Workbook

Sheet Plan1
B4: F2829V | C4: F2830H | D4: F2852H | E4: F2854H | F4: F2859H | G4: F2880H | H4: F2910H | I4: F2911V | J4: F2935H | K4: F2870H(6mm)
A5: Meso-macopores (v/v) | B5: =F2829V!$C$20 -> 0.35507795 | C5: =F2830H!$C$20 -> 0.57890019 | D5: =F2852H!$C$20 -> 0.69727902 | E5: =F2854H!$C$20 -> 0.97991361 | F5: =F2859H!$C$20 -> 0.97550208 | G5: =F2880H!$C$20 -> 0.90417019 | H5: =F2910H!$C$20 -> 0.93176598 | I5: =F2911V!$C$20 -> 0.92698342 | J5: =F2935H!$C$20 -> 0.92834408 | K5: =F2870H!$C$20 -> 0.99463573
A6: Aspect ratio Meso-macopores | B6: =F2829V!$B$48 -> 0.677752 | C6: =F2830H!$B$48 -> 0.55193587 | D6: =F2852H!$B$48 -> 0.58180851 | E6: =F2854H!$B$48 -> 0.53778411 | F6: =F2859H!$B$48 -> 0.53727093 | G6: =F2880H!$B$48 -> 0.56029398 | H6: =F2910H!$B$48 -> 0.56924221 | I6: =F2911V!$B$48 -> 0.54715049 | J6: =F2935H!$B$48 -> 0.55726415 | K6: =F2870H!$B$48 -> 0.55125387
A7: Micropores (v/v) | B7: =F2829V!$C$19 -> 0.64492205 | C7: =F2830H!$C$19 -> 0.42109981 | D7: =F2852H!$C$19 -> 0.30272098 | E7: =F2854H!$C$19 -> 0.020086387 | F7: =F2859H!$C$19 -> 0.024497923 | G7: =F2880H!$C$19 -> 0.095829811 | H7: =F2910H!$C$19 -> 0.068234023 | I7: =F2911V!$C$19 -> 0.073016581 | J7: =F2935H!$C$19 -> 0.071655921 | K7: =F2870H!$C$19 -> 0.0053642707
A8: Aspect ratio Micropores | B8: ? | C8: ? | D8: ? | E8: ? | F8: ? | G8: ? | H8: ? | I8: ? | J8: ? | K8: ?

Sheet Detected_pores
B1: 2D pore geometry and resolution - circunference approximation
B2: CT- resolutions for specimen in diameter: | C2: ~38 mm | D2: ~6 mm | E2: ~2.5 mm | I2: Micropores - Anselmetti et al. (1998), area < 500 µm²
B3: Minimum pixel (voxel) quantity for pore area | C3: 2 | D3: 2 | E3: 2 | I3: Circunference approximation | P3: Micro CT (sample ~38 mm in diameter) | Z3: Most significance
B4: Minimun pore area (pixel) | C4: =(C3)^2 -> 4 | D4: =(D3)^2 -> 4 | E4: =(E3)^2 -> 4 | I4: Minimun pore area (µm²) | J4: 500 | P4: Detected Minimun pore area (µm²) | Z4: =MIN(Q4:U4) -> 0
B5: Minimun pore diameter (pixel) | C5: =2*SQRT(C4/PI()) -> 2.2567583 | D5: =2*SQRT(D4/PI()) -> 2.2567583 | E5: =2*SQRT(E4/PI()) -> 2.2567583 | I5: Minimun pore diameter (µm) | J5: =2*SQRT(J4/PI()) -> 25.231325 | P5: Detected Maximun pore area (µm²) | Z5: =MAX(Q5:U5) -> 0
B6: Minimun pore radius (pixel) | C6: =SQRT(C4/PI()) -> 1.1283792 | D6: =SQRT(D4/PI()) -> 1.1283792 | E6: =SQRT(E4/PI()) -> 1.1283792 | I6: Minimun pore radius (µm) | J6: =SQRT(J4/PI()) -> 12.615663 | P6: Detected Maximun pore area (mm²) | Z6: =MAX(Q6:U6) -> 0
B7: Pixel (voxel) resolution (µm) | C7: 12.14 | D7: 3.33 | E7: 1.27 | P7: Detected Minimun pore diameter (µm) | Z7: =MIN(Q7:U7) -> 0
B8: Minimun pore area (µm²) | C8: =(C3*C7)^2 -> 589.5184 | D8: =(D3*D7)^2 -> 44.3556 | E8: =(E3*E7)^2 -> 6.4516 | P8: Detected Maximun pore diameter (µm) | Z8: =MAX(Q8:U8) -> 0
B9: Minimun pore diameter (µm) | C9: =2*SQRT(C8/PI()) -> 27.397046 | D9: =2*SQRT(D8/PI()) -> 7.5150053 | E9: =2*SQRT(E8/PI()) -> 2.8660831 | P9: Detected Maximun pore diameter (mm) | Z9: =MAX(Q9:U9) -> 0
B10: Minimun pore radius (µm) | C10: =SQRT(C8/PI()) -> 13.698523 | D10: =SQRT(D8/PI()) -> 3.7575026 | E10: =SQRT(E8/PI()) -> 1.4330415
P11: Micro CT (sample ~6 mm in diameter) | Q11: =F2870H!A1 -> F2870H(6mm) | Z11: Most significance
P12: Detected Minimun pore area (µm²) | Q12: =F2870H!$B$6 -> 177.53059 | Z12: =MIN(Q12:U12) -> 177.53059
B13: mm | C13: microns | P13: Detected Maximun pore area (µm²) | Q13: =F2870H!$B$7 -> 188673.67 | Z13: =MAX(Q13:U13) -> 188673.67
B14: 2.5 | C14: =B14*1000 -> 2500 | P14: Detected Maximun pore area (mm²) | Q14: =Q13*0.000001 -> 0.18867367 | Z14: =MAX(Q14:U14) -> 0.18867367
B15: 6 | C15: =B15*1000 -> 6000 | P15: Detected Minimun pore diameter (µm) | Q15: =F2870H!$B$9 -> 15.034592 | Z15: =MIN(Q15:U15) -> 15.034592
B16: 38 | C16: =B16*1000 -> 38000 | P16: Detected Maximun pore diameter (µm) | Q16: =F2870H!$B$10 -> 490.12935 | Z16: =MAX(Q16:U16) -> 490.12935
P17: Detected Maximun pore diameter (mm) | Q17: =Q16*0.001 -> 0.49012935 | Z17: =MAX(Q17:U17) -> 0.49012935
P19: Micro CT (sample ~2.5 mm in diameter) | Q19: =F2829V!A1 -> F2829V | R19: =F2830H!A1 -> F2830H | S19: =F2852H!A1 -> F2852H | T19: =F2854H!A1 -> F2854H | U19: =F2859H!A1 -> F2859H | V19: =F2880H!A1 -> F2880H | W19: =F2910H!A1 -> F2910H | X19: =F2911V!A1 -> F2911V | Y19: =F2935H!A1 -> F2935H | Z19: Most significance
P20: Detected Minimun pore area (µm²) | Q20: =F2829V!$B$6 -> 28.617086 | R20: =F2830H!$B$6 -> 22.978662 | S20: =F2852H!$B$6 -> 25.822136 | T20: =F2854H!$B$6 -> 28.617086 | U20: =F2859H!$B$6 -> 25.822136 | V20: =F2880H!$B$6 -> 25.822136 | W20: =F2910H!$B$6 -> 25.822136 | X20: =F2911V!$B$6 -> 25.822136 | Y20: =F2935H!$B$6 -> 25.822136 | Z20: =MIN(Q20:Y20) -> 22.978662
P21: Detected Maximun pore area (µm²) | Q21: =F2829V!$B$7 -> 2726.1217 | R21: =F2830H!$B$7 -> 21535.904 | S21: =F2852H!$B$7 -> 47268.675 | T21: =F2854H!$B$7 -> 342081.7 | U21: =F2859H!$B$7 -> 173392.68 | V21: =F2880H!$B$7 -> 280403.43 | W21: =F2910H!$B$7 -> 2982101.3 | X21: =F2911V!$B$7 -> 705065.97 | Y21: =F2935H!$B$7 -> 1052435 | Z21: =MAX(Q21:Y21) -> 2982101.3
P22: Detected Maximun pore area (mm²) | Q22: =Q21*0.000001 -> 0.0027261217 | R22: =R21*0.000001 -> 0.021535904 | S22: =S21*0.000001 -> 0.047268675 | T22: =T21*0.000001 -> 0.3420817 | U22: =U21*0.000001 -> 0.17339268 | V22: =V21*0.000001 -> 0.28040343 | W22: =W21*0.000001 -> 2.9821013 | X22: =X21*0.000001 -> 0.70506597 | Y22: =Y21*0.000001 -> 1.052435 | Z22: =MAX(Q22:Y22) -> 2.9821013
P23: Detected Minimun pore diameter (µm) | Q23: =F2829V!$B$9 -> 6.0362576 | R23: =F2830H!$B$9 -> 5.4090056 | S23: =F2852H!$B$9 -> 5.7339135 | T23: =F2854H!$B$9 -> 6.0362576 | U23: =F2859H!$B$9 -> 5.7339135 | V23: =F2880H!$B$9 -> 5.7339135 | W23: =F2910H!$B$9 -> 5.7339135 | X23: =F2911V!$B$9 -> 5.7339135 | Y23: =F2935H!$B$9 -> 5.7339135 | Z23: =MIN(Q23:Y23) -> 5.4090056
P24: Detected Maximun pore diameter (µm) | Q24: =F2829V!$B$10 -> 58.915243 | R24: =F2830H!$B$10 -> 165.59096 | S24: =F2852H!$B$10 -> 245.32498 | T24: =F2854H!$B$10 -> 659.9636 | U24: =F2859H!$B$10 -> 469.86213 | V24: =F2880H!$B$10 -> 597.51213 | W24: =F2910H!$B$10 -> 1948.5711 | X24: =F2911V!$B$10 -> 947.47975 | Y24: =F2829V!$B$10 -> 58.915243 | Z24: =MAX(Q24:Y24) -> 1948.5711
P25: Detected Maximun pore diameter (mm) | Q25: =Q24*0.001 -> 0.058915243 | R25: =R24*0.001 -> 0.16559096 | S25: =S24*0.001 -> 0.24532498 | T25: =T24*0.001 -> 0.6599636 | U25: =U24*0.001 -> 0.46986213 | V25: =V24*0.001 -> 0.59751213 | W25: =W24*0.001 -> 1.9485711 | X25: =X24*0.001 -> 0.94747975 | Y25: =Y24*0.001 -> 0.058915243 | Z25: =MAX(Q25:Y25) -> 1.9485711

Sheet Mineral dual thresh
P1: Volume Corrected
C2: Multi Threshold (dual) - CT specimen Well 861 | P2: Multi Threshold (dual) - CT specimen Well 861
B3: GeoDict | C3: Phase | D3: F2829V | E3: F2830H | F3: F2852H | G3: F2854H | H3: F2859H | I3: F2880H | J3: F2910H | K3: F2911V | L3: F2935H | M3: F2870H(6mm) | O3: GeoDict | P3: Phase | Q3: F2829V | R3: F2830H | S3: F2852H | T3: F2854H | U3: F2859H | V3: F2880H | W3: F2910H | X3: F2911V | Y3: F2935H | Z3: F2870H(6mm)
B4: Original | C4: Pore (%) | D4: 0.01 | E4: 4.9 | F4: 2.4 | G4: 3.1 | H4: 3.93 | I4: 9.3 | J4: 9.37 | K4: 11.7 | L4: 14.11 | M4: 0.38 | O4: Corrected | P4: Pore (%) | Q4: =(D12/SUM(D12:D14))*100 -> 0.012732366 | R4: =(E12/SUM(E12:E14))*100 -> 6.3332041 | S4: =(F12/SUM(F12:F14))*100 -> 3.0557678 | T4: =(G12/SUM(G12:G14))*100 -> 3.9470334 | U4: =(H12/SUM(H12:H14))*100 -> 5.0038197 | V4: =(I12/SUM(I12:I14))*100 -> 11.8411 | W4: =(J12/SUM(J12:J14))*100 -> 11.975971 | X4: =(K12/SUM(K12:K14))*100 -> 14.896868 | ... Z4: =(M12/SUM(M12:M14))*100 -> 0.4837683
C5: Solid 1 (%) | D5: 38.84 | E5: 68.36 | F5: 13.83 | G5: 73.66 | H5: 21.03 | I5: 23.32 | J5: 10.67 | K5: 63.57 | L5: 58.77 | M5: 74.89 | P5: Solid 1 (%) | Q5: =(D13/SUM(D12:D14))*100 -> 49.452508 | R5: =(E13/SUM(E12:E14))*100 -> 88.354659 | S5: =(F13/SUM(F12:F14))*100 -> 17.608862 | T5: =(G13/SUM(G12:G14))*100 -> 93.786606 | U5: =(H13/SUM(H12:H14))*100 -> 26.776165 | V5: =(I13/SUM(I12:I14))*100 -> 29.691877 | W5: =(J13/SUM(J12:J14))*100 -> 13.637526 | X5: =(K13/SUM(K12:K14))*100 -> 80.939649 | ... Z5: =(M13/SUM(M12:M14))*100 -> 95.340547
C6: Solid 2 (%) | D6: 39.69 | E6: 4.11 | F6: 62.31 | G6: 1.78 | H6: 53.58 | I6: 45.92 | J6: 58.2 | K6: 3.27 | L6: 5.66 | M6: 3.28 | P6: Solid 2 (%) | Q6: =(D14/SUM(D12:D14))*100 -> 50.534759 | R6: =(E14/SUM(E12:E14))*100 -> 5.3121365 | S6: =(F14/SUM(F12:F14))*100 -> 79.335371 | T6: =(G14/SUM(G12:G14))*100 -> 2.2663611 | U6: =(H14/SUM(H12:H14))*100 -> 68.220015 | V6: =(I14/SUM(I12:I14))*100 -> 58.467023 | W6: =(J14/SUM(J12:J14))*100 -> 74.386503 | X6: =(K14/SUM(K12:K14))*100 -> 4.1634836 | ... Z6: =(M14/SUM(M12:M14))*100 -> 4.1756843
C7: Undefined (%) | D7: =100-SUM(D4:D6) -> 21.46 | E7: =100-SUM(E4:E6) -> 22.63 | F7: =100-SUM(F4:F6) -> 21.46 | G7: =100-SUM(G4:G6) -> 21.46 | H7: =100-SUM(H4:H6) -> 21.46 | I7: =100-SUM(I4:I6) -> 21.46 | J7: =100-SUM(J4:J6) -> 21.76 | K7: =100-SUM(K4:K6) -> 21.46 | ... M7: =100-SUM(M4:M6) -> 21.45 | P7: Sum (%) | Q7: =SUM(Q4:Q6) -> 100 | R7: =SUM(R4:R6) -> 100 | S7: =SUM(S4:S6) -> 100 | T7: =SUM(T4:T6) -> 100 | U7: =SUM(U4:U6) -> 100 | V7: =SUM(V4:V6) -> 100 | W7: =SUM(W4:W6) -> 100 | X7: =SUM(X4:X6) -> 100 | ... Z7: =SUM(Z4:Z6) -> 100
C8: NX (mm) | D8: 2.21742 | E8: 2.20472 | F8: 2.18059 | G8: 2.32156 | H8: 2.26568 | I8: 2.2098 | J8: 1.87706 | K8: 2.24155 | L8: 2.21869 | M8: 4.73526
C9: NY (mm) | D9: 1.97358 | E9: 2.20472 | F9: 2.18059 | G9: 2.32156 | H9: 2.26568 | I9: 2.2098 | J9: 1.87706 | K9: 2.24155 | L9: 2.21869 | M9: 4.73526
C10: NZ (mm) | D10: 1.49098 | E10: 2.40792 | F10: 2.40157 | G10: 2.56286 | H10: 2.57556 | I10: 2.57556 | J10: 2.58445 | K10: 2.58445 | L10: 2.41554 | M10: 6.64668
C11: Domain Vol (mm³) | D11: =PRODUCT(D8:D10) -> 6.5249098 | E11: =PRODUCT(E8:E10) -> 11.704394 | F11: =PRODUCT(F8:F10) -> 11.4194 | G11: =PRODUCT(G8:G10) -> 13.812895 | H11: =PRODUCT(H8:H10) -> 13.221137 | I11: =PRODUCT(I8:I10) -> 12.577016 | J11: =PRODUCT(J8:J10) -> 9.1059329 | K11: =PRODUCT(K8:K10) -> 12.985689 | ... M11: =PRODUCT(M8:M10) -> 149.03643
C12: Pore (mm³) | D12: =D$11*(D4/100) -> 0.00065249098 | E12: =E$11*(E4/100) -> 0.57351531 | F12: =F$11*(F4/100) -> 0.2740656 | G12: =G$11*(G4/100) -> 0.42819974 | H12: =H$11*(H4/100) -> 0.51959069 | I12: =I$11*(I4/100) -> 1.1696625 | J12: =J$11*(J4/100) -> 0.85322591 | K12: =K$11*(K4/100) -> 1.5193256 | ... M12: =M$11*(M4/100) -> 0.56633842
C13: Solid 1 (mm³) | D13: =D$11*(D5/100) -> 2.534275 | E13: =E$11*(E5/100) -> 8.0011238 | F13: =F$11*(F5/100) -> 1.579303 | G13: =G$11*(G5/100) -> 10.174578 | H13: =H$11*(H5/100) -> 2.7804052 | I13: =I$11*(I5/100) -> 2.9329601 | J13: =J$11*(J5/100) -> 0.97160304 | K13: =K$11*(K5/100) -> 8.2550025 | ... M13: =M$11*(M5/100) -> 111.61338
C14: Solid 2 (mm³) | D14: =D$11*(D6/100) -> 2.5897367 | E14: =E$11*(E6/100) -> 0.4810506 | F14: =F$11*(F6/100) -> 7.1154281 | G14: =G$11*(G6/100) -> 0.24586953 | H14: =H$11*(H6/100) -> 7.0838853 | I14: =I$11*(I6/100) -> 5.7753657 | J14: =J$11*(J6/100) -> 5.2996529 | K14: =K$11*(K6/100) -> 0.42463203 | ... M14: =M$11*(M6/100) -> 4.8883948
C15: Undefined (mm³) | D15: =D$11*(D7/100) -> 1.4002456 | E15: =E$11*(E7/100) -> 2.6487044 | F15: =F$11*(F7/100) -> 2.4506032 | G15: =G$11*(G7/100) -> 2.9642472 | H15: =H$11*(H7/100) -> 2.8372561 | I15: =I$11*(I7/100) -> 2.6990276 | J15: =J$11*(J7/100) -> 1.981451 | K15: =K$11*(K7/100) -> 2.7867288 | ... M15: =M$11*(M7/100) -> 31.968314
C18: Mineralogy (%) and supposed gray scale | G18: Test 1 | I18: Test 2
D19: XRD and Rietveld Method | G19: Supposed occurrence | I19: Supposed occurrence
A20: Texture (ANP Petrobras) | B20: Texture (LENEP) | C20: Sample | D20: Calcite | E20: Dolomite | F20: Quartz | G20: Quartz (Solid 1) | H20: Calcite + Dolomite (Solid 2) | I20: Quartz + Calcite (Solid 1) | J20: Dolomite (Solid 2)
A21: Grainstone/Rudstone | B21: Packstone | C21: F2829V | D21: 78 | E21: 13 | F21: =100-(D21+E21) -> 9 | G21: =F21 -> 9 | H21: =100-G21 -> 91 | I21: =F21+D21 -> 87 | J21: =E21 -> 13
A22: Grainstone/Rudstone | B22: Packstone | C22: F2830H | D22: 24 | E22: 6 | F22: =100-(D22+E22) -> 70 | G22: =F22 -> 70 | H22: =100-G22 -> 30 | I22: =F22+D22 -> 94 | J22: =E22 -> 6
A23: Laminite/Grainstone | B23: Packstone | C23: F2852H | D23: 32 | E23: 43 | F23: =100-(D23+E23) -> 25 | G23: =F23 -> 25 | H23: =100-G23 -> 75 | I23: =F23+D23 -> 57 | J23: =E23 -> 43
A24: Shrubs | B24: Grainstone | C24: F2854H | D24: 69 | E24: 25 | F24: =100-(D24+E24) -> 6 | G24: =F24 -> 6 | H24: =100-G24 -> 94 | I24: =F24+D24 -> 75 | J24: =E24 -> 25
A25: Shrubs/Rudstone | B25: Spherulistone | C25: F2859H | D25: 62 | E25: 20 | F25: =100-(D25+E25) -> 18 | G25: =F25 -> 18 | H25: =100-G25 -> 82 | I25: =F25+D25 -> 80 | J25: =E25 -> 20
A26: Shrubs/Grainstone | B26: Shrubby spherulitestone | C26: F2880H | D26: 29 | E26: 54 | F26: =100-(D26+E26) -> 17 | G26: =F26 -> 17 | H26: =100-G26 -> 83 | I26: =F26+D26 -> 46 | J26: =E26 -> 54
A27: Spherulitestone/Grainstone | B27: spherulitestone | C27: F2910H | D27: 60 | E27: 33 | F27: =100-(D27+E27) -> 7 | G27: =F27 -> 7 | H27: =100-G27 -> 93 | I27: =F27+D27 -> 67 | J27: =E27 -> 33
A28: Spherulitestone/Grainstone | B28: spherulitestone | C28: F2911V | D28: 54 | E28: 34 | F28: =100-(D28+E28) -> 12 | G28: =F28 -> 12 | H28: =100-G28 -> 88 | I28: =F28+D28 -> 66 | J28: =E28 -> 34
A29: Shrubs/Grainstone | B29: Grainstone | C29: F2935H | D29: 51 | E29: 40 | F29: =100-(D29+E29) -> 9 | G29: =F29 -> 9 | H29: =100-G29 -> 91 | I29: =F29+D29 -> 60 | J29: =E29 -> 40
A30: Grainstone/Shrubs | B30: Spherulitic shrubstone | C30: F2870H(6mm) | D30: 72 | E30: 22 | F30: =100-(D30+E30) -> 6 | G30: =F30 -> 6 | H30: =100-G30 -> 94 | I30: =F30+D30 -> 78 | J30: =E30 -> 22
C31: Mineral density (g/cc): | D31: 2.71 | E31: 2.87 | F31: 2.65 | G31: =F31 -> 2.65 | H31: 2.71-2.87 | I31: 2.65-2.71 | J31: 2.87
C32: Legend:
D33: - Dry pore (air): 0.00119 g/cc.
C34: * 8 bit Gray level is supposed to be related to the phase density:
D35: - Quartz (Terrigenous)
D36: - Calcite + Dolomite (Carbonate)
C37: * Mineral and air densities from Mavko et al. (2009).

Sheet Plots
AI1: Diff. Lab and DIA
A2: 0.1 | P2: Mean (average) | R2: Micro CT - Well 861 | AF2: Volume Corrected | AI2: Corrected
A3: 0.2 | N3: Depth | O3: Sample | P3: Pore Aspect Ratio | R3: Porosity occurence (%) (Anselmetti et al., 1998): | AE3: UltraPore Porosity (%) | AF3: Image Porosity (%) | AI3: Porosity (%) | AK3: Porosity (%) | AM3: Porosity (%) | AO3: Porosity (%) | AQ3: Porosity (%) | AS3: Porosity (%) | AU3: Porosity (%) | AW3: Porosity (%)
A4: 0.3 | N4: 5206 | O4: =F2829V!$A$1 -> F2829V | P4: =F2829V!$B$48 -> 0.677752 | S4: =F2829V!$A$1 -> F2829V | T4: =F2830H!$A$1 -> F2830H | U4: =F2852H!$A$1 -> F2852H | V4: =F2854H!$A$1 -> F2854H | W4: =F2859H!$A$1 -> F2859H | X4: =F2880H!$A$1 -> F2880H | Y4: =F2910H!$A$1 -> F2910H | Z4: =F2911V!$A$1 -> F2911V | AA4: =F2935H!$A$1 -> F2935H | AB4: =F2870H!$A$1 -> F2870H(6mm) | AD4: Sample | AE4: Ambient | AF4: MicroCT | AG4: Macro-meso | AH4: Micro | AI4: Micro | AJ4: 5.5 MPa | AK4: Micro | AL4: 8.3 MPa | AM4: Micro | AN4: 11 MPa | AO4: Micro | AP4: 13.8 MPa | AQ4: Micro | AR4: 16.5 MPa | AS4: Micro | AT4: 19.3 MPa | AU4: Micro | AV4: 22.1 MPa | AW4: Micro
A5: 0.4 | N5: 5206.05 | O5: =F2830H!$A$1 -> F2830H | P5: =F2830H!$B$48 -> 0.55193587 | R5: < 5E2 (µm²) -> micropore | S5: =F2829V!$B$44 -> 0.0040378841 | T5: =F2830H!$B$44 -> 2.0128435 | U5: =F2852H!$B$44 -> 0.71129622 | V5: =F2854H!$B$44 -> 0.058768827 | W5: =F2859H!$B$44 -> 0.092906754 | X5: =F2880H!$B$44 -> 0.87282734 | Y5: =F2910H!$B$44 -> 0.59090499 | Z5: =F2911V!$B$44 -> 0.82408015 | AA5: =F2935H!$B$44 -> 0.9793008 | AB5: =F2870H!$B$44 -> 0.0019874236 | AD5: =F2829V!$A$1 -> F2829V | AE5: 6.7234 | AF5: =S9 -> 0.01 | AG5: =S9*F2829V!C20 -> 0.0035507795 | AH5: =S9*F2829V!C19 -> 0.0064492205 | AI5: Not measured.
A6: 0.5 | N6: 5211.4 | O6: =F2852H!$A$1 -> F2852H | P6: =F2852H!$B$48 -> 0.58180851 | R6: 5E2:5E3 (µm²) | S6: =F2829V!$B$45 -> 0.0022352471 | T6: =F2830H!$B$45 -> 2.653495 | U6: =F2852H!$B$45 -> 1.4905401 | V6: =F2854H!$B$45 -> 0.81398293 | W6: =F2859H!$B$45 -> 1.4059916 | X6: =F2880H!$B$45 -> 5.4803081 | Y6: =F2910H!$B$45 -> 3.2975978 | Z6: =F2911V!$B$45 -> 5.3036508 | AA6: =F2935H!$B$45 -> 5.6283702 | AB6: =F2870H!$B$45 -> 0.12448357 | AD6: =F2830H!$A$1 -> F2830H | AE6: 3.7824 | AF6: =T9 -> 4.9 | AG6: =T9*F2830H!C20 -> 2.8366109 | AH6: =T9*F2830H!C19 -> 2.0633891
A7: 0.6 | N7: 5212.05 | O7: =F2854H!$A$1 -> F2854H | P7: =F2854H!$B$48 -> 0.53778411 | R7: 5E3:5E4 (µm²) | S7: =F2829V!$B$46 -> 0 | T7: =F2830H!$B$46 -> 0.12672928 | U7: =F2852H!$B$46 -> 0.15298458 | V7: =F2854H!$B$46 -> 1.5248234 | W7: =F2859H!$B$46 -> 1.9686539 | X7: =F2880H!$B$46 -> 2.4738065 | Y7: =F2910H!$B$46 -> 3.6525065 | Z7: =F2911V!$B$46 -> 3.9823164 | AA7: =F2935H!$B$46 -> 5.8716376 | AB7: =F2935H!$B$46 -> 5.8716376 | AD7: =F2852H!$A$1 -> F2852H | AE7: 1.3284 | AF7: =U9 -> 2.4 | AG7: =U9*F2852H!C20 -> 1.6734696 | AH7: =U9*F2852H!C19 -> 0.72653035
A8: 0.7 | N8: 5212.9 | O8: =F2859H!$A$1 -> F2859H | P8: =F2859H!$B$48 -> 0.53727093 | R8: > 5E4 (µm²) | S8: =F2829V!$B$47 -> 0 | T8: =F2830H!$B$47 -> 0 | U8: =F2852H!$B$47 -> 0 | V8: =F2854H!$B$47 -> 0.53287975 | W8: =F2859H!$B$47 -> 0.33187219 | X8: =F2880H!$B$47 -> 0.30520454 | Y8: =F2910H!$B$47 -> 1.1498357 | Z8: =F2911V!$B$47 -> 1.2062165 | AA8: =F2935H!$B$47 -> 1.2216663 | AB8: =F2870H!$B$47 -> 0.025390158 | AD8: =F2854H!$A$1 -> F2854H | AE8: 8.0284 | AF8: =V9 -> 3.1 | AG8: =V9*F2854H!C20 -> 3.0377322 | AH8: =V9*F2854H!C19 -> 0.062267798
A9: 0.8 | N9: 5218.25 | O9: =F2880H!$A$1 -> F2880H | P9: =F2880H!$B$48 -> 0.56029398 | R9: TOMO Image Porosity (%) - volume corrected | S9: ='Mineral dual thresh'!D4 -> 0.01 | T9: ='Mineral dual thresh'!E4 -> 4.9 | U9: ='Mineral dual thresh'!F4 -> 2.4 | V9: ='Mineral dual thresh'!G4 -> 3.1 | W9: ='Mineral dual thresh'!H4 -> 3.93 | X9: ='Mineral dual thresh'!I4 -> 9.3 | Y9: ='Mineral dual thresh'!J4 -> 9.37 | Z9: ='Mineral dual thresh'!K4 -> 11.7 | ... AB9: ='Mineral dual thresh'!M4 -> 0.38 | AD9: =F2859H!$A$1 -> F2859H | AE9: 6.37 | AF9: =W9 -> 3.93 | AG9: =W9*F2859H!C20 -> 3.8337232 | AH9: =W9*F2859H!C19 -> 0.096276838
A10: 0.9 | N10: 5225.7 | O10: =F2910H!$A$1 -> F2910H | P10: =F2910H!$B$48 -> 0.56924221 | R10: Lab Porosity (ambient-Ultrapore) (%) | S10: 6.7234 | T10: 3.7824 | U10: 1.3284 | V10: 8.0284 | W10: 6.37 | X10: 13.7158 | Y10: 14.6312 | Z10: 23.7334 | AA10: 12.8634 | AB10: 4.461 | AD10: =F2880H!$A$1 -> F2880H | AE10: 13.7158 | AF10: =X9 -> 9.3 | AG10: =X9*F2880H!C20 -> 8.4087828 | AH10: =X9*F2880H!C19 -> 0.89121724
A11: 1 | N11: 5225.75 | O11: =F2911V!$A$1 -> F2911V | P11: =F2911V!$B$48 -> 0.54715049 | R11: Difference (%) | S11: =S10-S9 -> 6.7134 | T11: =T10-T9 -> -1.1176 | U11: =U10-U9 -> -1.0716 | V11: =V10-V9 -> 4.9284 | W11: =W10-W9 -> 2.44 | X11: =X10-X9 -> 4.4158 | Y11: =Y10-Y9 -> 5.2612 | Z11: =Z10-Z9 -> 12.0334 | ... AB11: =AB10-AB9 -> 4.081 | AD11: =F2910H!$A$1 -> F2910H | AE11: 14.6312 | AF11: =Y9 -> 9.37 | AG11: =Y9*F2910H!C20 -> 8.7306472 | AH11: =Y9*F2910H!C19 -> 0.63935279
N12: 5232.25 | O12: =F2935H!$A$1 -> F2935H | P12: =F2935H!$B$48 -> 0.55726415 | R12: Fraction Macro-meso (0-1) | S12: =S9/S10 -> 0.0014873427 | T12: =T9/T10 -> 1.2954738 | U12: =U9/U10 -> 1.8066847 | V12: =V9/V10 -> 0.38612924 | W12: =W9/W10 -> 0.61695447 | X12: =X9/X10 -> 0.67805013 | Y12: =Y9/Y10 -> 0.64041227 | Z12: =Z9/Z10 -> 0.49297614 | ... AB12: =AB9/AB10 -> 0.085182694 | AD12: =F2911V!$A$1 -> F2911V | AE12: 23.7334 | AF12: =Z9 -> 11.7 | AG12: =Z9*F2911V!C20 -> 10.845706 | AH12: =Z9*F2911V!C19 -> 0.85429399
N13: 5215.55 | O13: =F2870H!$A$1 -> F2870H(6mm) | P13: =F2870H!$B$48 -> 0.55125387 | R13: Fraction Micro (0-1) | S13: =S11/S10 -> 0.99851266 | T13: =T11/T10 -> -0.29547377 | U13: =U11/U10 -> -0.80668473 | V13: =V11/V10 -> 0.61387076 | W13: =W11/W10 -> 0.38304553 | X13: =X11/X10 -> 0.32194987 | Y13: =Y11/Y10 -> 0.35958773 | Z13: =Z11/Z10 -> 0.50702386 | ... AB13: =AB11/AB10 -> 0.91481731 | AD13: =F2935H!$A$1 -> F2935H | AE13: 12.8634 | AF13: =AA9 -> 14.11 | AG13: =AA9*F2935H!C20 -> 13.098935 | AH13: =AA9*F2935H!C19 -> 1.011065
R14: Detected Minimun pore area (µm²) | S14: =F2829V!$B$6 -> 28.617086 | T14: =F2830H!$B$6 -> 22.978662 | U14: =F2852H!$B$6 -> 25.822136 | V14: =F2854H!$B$6 -> 28.617086 | W14: =F2859H!$B$6 -> 25.822136 | X14: =F2880H!$B$6 -> 25.822136 | Y14: =F2910H!$B$6 -> 25.822136 | Z14: =F2911V!$B$6 -> 25.822136 | AA14: =F2935H!$B$6 -> 25.822136 | AB14: =F2935H!$B$6 -> 25.822136 | AD14: =F2870H!$A$1 -> F2870H(6mm) | AE14: =AB10 -> 4.461 | AF14: =AB9 -> 0.38 | AG14: =AB9*F2870H!C20 -> 0.37796158 | AH14: =AB9*F2870H!C19 -> 0.0020384229
R15: Detected Maximun pore area (µm²) | S15: =F2829V!$B$7 -> 2726.1217 | T15: =F2830H!$B$7 -> 21535.904 | U15: =F2852H!$B$7 -> 47268.675 | V15: =F2854H!$B$7 -> 342081.7 | W15: =F2859H!$B$7 -> 173392.68 | X15: =F2880H!$B$7 -> 280403.43 | Y15: =F2910H!$B$7 -> 2982101.3 | Z15: =F2911V!$B$7 -> 705065.97 | AA15: =F2935H!$B$7 -> 1052435 | AB15: =F2935H!$B$7 -> 1052435
R16: Detected Maximun pore area (mm²) | S16: =S15*0.000001 -> 0.0027261217 | T16: =T15*0.000001 -> 0.021535904 | U16: =U15*0.000001 -> 0.047268675 | V16: =V15*0.000001 -> 0.3420817 | W16: =W15*0.000001 -> 0.17339268 | X16: =X15*0.000001 -> 0.28040343 | Y16: =Y15*0.000001 -> 2.9821013 | Z16: =Z15*0.000001 -> 0.70506597 | ... AB16: =AB15*0.000001 -> 1.052435
R17: Detected Minimun pore diameter (µm) | S17: =F2829V!$B$9 -> 6.0362576 | T17: =F2830H!$B$9 -> 5.4090056 | U17: =F2852H!$B$9 -> 5.7339135 | V17: =F2854H!$B$9 -> 6.0362576 | W17: =F2859H!$B$9 -> 5.7339135 | X17: =F2829V!$B$9 -> 6.0362576 | Y17: =F2830H!$B$9 -> 5.4090056 | Z17: =F2852H!$B$9 -> 5.7339135 | AA17: =F2854H!$B$9 -> 6.0362576 | AB17: =F2854H!$B$9 -> 6.0362576
R18: Detected Maximun pore diameter (µm) | S18: =F2829V!$B$10 -> 58.915243 | T18: =F2830H!$B$10 -> 165.59096 | U18: =F2852H!$B$10 -> 245.32498 | V18: =F2854H!$B$10 -> 659.9636 | W18: =F2859H!$B$10 -> 469.86213 | X18: =F2829V!$B$10 -> 58.915243 | Y18: =F2830H!$B$10 -> 165.59096 | Z18: =F2852H!$B$10 -> 245.32498 | AA18: =F2854H!$B$10 -> 659.9636 | AB18: =F2854H!$B$10 -> 659.9636
R19: Detected Maximun pore diameter (mm) | S19: =S18*0.001 -> 0.058915243 | T19: =T18*0.001 -> 0.16559096 | U19: =U18*0.001 -> 0.24532498 | V19: =V18*0.001 -> 0.6599636 | W19: =W18*0.001 -> 0.46986213 | X19: =X18*0.001 -> 0.058915243 | Y19: =Y18*0.001 -> 0.16559096 | Z19: =Z18*0.001 -> 0.24532498 | ... AB19: =AB18*0.001 -> 0.6599636

Sheet F2829V
A1: F2829V
A2: LOCAL PORE PARAMETERS
A3: Pixel resolution (microns) | B3: 1.27
A4: Minimum pixel quantity for pore area | B4: 2
A5: Pore area resolution (microns^2) | B5: 6.4516
A6: Minor pore area (microns^2) | B6: 28.617086
A7: Maximum pore area (microns^2) | B7: 2726.1217
A8: Mean pore area (microns^2) | B8: 227.56565
A9: Minor pore diameter (microns) | B9: 6.0362576
A10: Maximum pore diameter (microns) | B10: 58.915243
A11: Mean pore diameter (microns) | B11: 15.77852
A12: Minor pore radius (microns) | B12: 3.0181288
A13: Maximum pore radius (microns) | B13: 29.457622
A14: Mean pore radius (microns) | B14: 7.88926
... A17: Mean pore perimeter (microns) | B17: 21.72924
A18: Porosity (%) | B18: 0.0062950883 | C18: Fraction:
A19: Microcroporosity (%) (Anselmetti et al., 1998) | B19: 0.0040598413 | C19: =B19/B18 -> 0.64492205
A20: Macro-mesoporosity (%) (Anselmetti et al., 1998) | B20: 0.0022352471 | C20: =B20/B18 -> 0.35507795
A21: Mean Pore area Microporosity (microns^2)(Anselmetti et al., 1998) | B21: 182.29479
A22: Mean Pore area Macro-mesoporosity (microns^2) (Anselmetti et al., 1998) | B22: 757.02488
A23: Mean Pore perimeter Microporosity (microns) (Anselmetti et al., 1998) | B23: 20.412238
A24: Mean Pore perimeter Macro-mesoporosity (microns) (Anselmetti et al., 1998) | B24: 37.132055
A25: Mean Pore radius Microporosity(microns) (Anselmetti et al., 1998) | B25: 7.2610445
A26: Mean Pore radius Macro-mesoporosity(microns) (Anselmetti et al., 1998) | B26: 15.236469
A27: Mean Gamma | B27: 0.44771114
A28: Mean Gamma Microporosity (Anselmetti et al., 1998) | B28: 0.45260748
A29: Mean Gamma Macro-mesoporosity (Anselmetti et al., 1998) | B29: 0.39044665
A30: Mean Fps (microns^-1) (equal to gamma^2) | B30: 0.20044527
A31: Mean Fps Microporosity (microns^-1) (Anselmetti et al., 1998) (microns^-1) | B31: 0.20485353
A32: Mean Fps Macro-mesoporosity (microns^-1) (Anselmetti et al., 1998) (microns^-1) | B32: 0.15244859
... A39: Permeability (Kozeny-Carman) (mD) | B39: 0.44401817
A40: Porosity area occurence (Anselmetti et al., 1998): | B40: %
A41: <0.5 | B41: 0
A42: 0.5:5 | B42: 0
A43: 5:5E1 | B43: 2.1957203e-05
A44: 5E1:5E2 | B44: 0.0040378841
A45: 5E2:5E3 | B45: 0.0022352471
A46: 5E3:5E4 | B46: 0
A47: >5E4 | B47: 0
A48: Mean Aspect Ratio | B48: 0.677752
...

Sheet F2830H
A1: F2830H
A2: LOCAL PORE PARAMETERS
A3: Pixel resolution (microns) | B3: 1.27
A4: Minimum pixel quantity for pore area | B4: 2
A5: Pore area resolution (microns^2) | B5: 6.4516
A6: Minor pore area (microns^2) | B6: 22.978662
A7: Maximum pore area (microns^2) | B7: 21535.904
A8: Mean pore area (microns^2) | B8: 273.52995
A9: Minor pore diameter (microns) | B9: 5.4090056
A10: Maximum pore diameter (microns) | B10: 165.59096
A11: Mean pore diameter (microns) | B11: 16.620004
A12: Minor pore radius (microns) | B12: 2.7045028
A13: Maximum pore radius (microns) | B13: 82.795478
A14: Mean pore radius (microns) | B14: 8.3100021
... A17: Mean pore perimeter (microns) | B17: 20.747605
A18: Porosity (%) | B18: 4.802597 | C18: Fraction:
A19: Microcroporosity (%) (Anselmetti et al., 1998) | B19: 2.0223727 | C19: =B19/B18 -> 0.42109981
A20: Macro-mesoporosity (%) (Anselmetti et al., 1998) | B20: 2.7802243 | C20: =B20/B18 -> 0.57890019
A21: Mean Pore area Microporosity (microns^2)(Anselmetti et al., 1998) | B21: 173.08715
A22: Mean Pore area Macro-mesoporosity (microns^2) (Anselmetti et al., 1998) | B22: 983.12221
A23: Mean Pore perimeter Microporosity (microns) (Anselmetti et al., 1998) | B23: 18.136158
A24: Mean Pore perimeter Macro-mesoporosity (microns) (Anselmetti et al., 1998) | B24: 39.19654
A25: Mean Pore radius Microporosity(microns) (Anselmetti et al., 1998) | B25: 7.0773689
A26: Mean Pore radius Macro-mesoporosity(microns) (Anselmetti et al., 1998) | B26: 17.018112
A27: Mean Gamma | B27: 0.4080966
A28: Mean Gamma Microporosity (Anselmetti et al., 1998) | B28: 0.41355265
A29: Mean Gamma Macro-mesoporosity (Anselmetti et al., 1998) | B29: 0.36955154
A30: Mean Fps (microns^-1) (equal to gamma^2) | B30: 0.16654283
A31: Mean Fps Microporosity (microns^-1) (Anselmetti et al., 1998) (microns^-1) | B31: 0.17102579
A32: Mean Fps Macro-mesoporosity (microns^-1) (Anselmetti et al., 1998) (microns^-1) | B32: 0.13656834
... A39: Permeability (Kozeny-Carman) (mD) | B39: 416.32125
A40: Porosity area occurence (Anselmetti et al., 1998): | B40: %
A41: <0.5 | B41: 0
A42: 0.5:5 | B42: 0
A43: 5:5E1 | B43: 0.0095291755
A44: 5E1:5E2 | B44: 2.0128435
A45: 5E2:5E3 | B45: 2.653495
A46: 5E3:5E4 | B46: 0.12672928
A47: >5E4 | B47: 0
A48: Mean Aspect Ratio | B48: 0.55193587
...

Sheet F2852H
A1: F2852H
A2: LOCAL PORE PARAMETERS
A3: Pixel resolution (microns) | B3: 1.27
A4: Minimum pixel quantity for pore area | B4: 2
A5: Pore area resolution (microns^2) | B5: 6.4516
A6: Minor pore area (microns^2) | B6: 25.822136
A7: Maximum pore area (microns^2) | B7: 47268.675
A8: Mean pore area (microns^2) | B8: 378.29286
A9: Minor pore diameter (microns) | B9: 5.7339135
A10: Maximum pore diameter (microns) | B10: 245.32498
A11: Mean pore diameter (microns) | B11: 19.527117
A12: Minor pore radius (microns) | B12: 2.8669568
A13: Maximum pore radius (microns) | B13: 122.66249
A14: Mean pore radius (microns) | B14: 9.7635584
... A17: Mean pore perimeter (microns) | B17: 25.004437
A18: Porosity (%) | B18: 2.3570546 | C18: Fraction:
A19: Microcroporosity (%) (Anselmetti et al., 1998) | B19: 0.71352988 | C19: =B19/B18 -> 0.30272098
A20: Macro-mesoporosity (%) (Anselmetti et al., 1998) | B20: 1.6435247 | C20: =B20/B18 -> 0.69727902
A21: Mean Pore area Microporosity (microns^2)(Anselmetti et al., 1998) | B21: 206.5264
A22: Mean Pore area Macro-mesoporosity (microns^2) (Anselmetti et al., 1998) | B22: 1006.0147
A23: Mean Pore perimeter Microporosity (microns) (Anselmetti et al., 1998) | B23: 20.62037
A24: Mean Pore perimeter Macro-mesoporosity (microns) (Anselmetti et al., 1998) | B24: 41.026044
A25: Mean Pore radius Microporosity(microns) (Anselmetti et al., 1998) | B25: 7.7432588
A26: Mean Pore radius Macro-mesoporosity(microns) (Anselmetti et al., 1998) | B26: 17.146758
A27: Mean Gamma | B27: 0.41953409
A28: Mean Gamma Microporosity (Anselmetti et al., 1998) | B28: 0.42926941
A29: Mean Gamma Macro-mesoporosity (Anselmetti et al., 1998) | B29: 0.38395627
A30: Mean Fps (microns^-1) (equal to gamma^2) | B30: 0.17600885
A31: Mean Fps Microporosity (microns^-1) (Anselmetti et al., 1998) (microns^-1) | B31: 0.18427222
A32: Mean Fps Macro-mesoporosity (microns^-1) (Anselmetti et al., 1998) (microns^-1) | B32: 0.14742242
... A39: Permeability (Kozeny-Carman) (mD) | B39: 251.13287
A40: Porosity area occurence (Anselmetti et al., 1998): | B40: %
A41: <0.5 | B41: 0
A42: 0.5:5 | B42: 0
A43: 5:5E1 | B43: 0.002233662
A44: 5E1:5E2 | B44: 0.71129622
A45: 5E2:5E3 | B45: 1.4905401
A46: 5E3:5E4 | B46: 0.15298458
A47: >5E4 | B47: 0
A48: Mean Aspect Ratio | B48: 0.58180851
...

Sheet F2854H
A1: F2854H
A2: LOCAL PORE PARAMETERS
A3: Pixel resolution (microns) | B3: 1.27
A4: Minimum pixel quantity for pore area | B4: 2
A5: Pore area resolution (microns^2) | B5: 6.4516
A6: Minor pore area (microns^2) | B6: 28.617086
A7: Maximum pore area (microns^2) | B7: 342081.7
A8: Mean pore area (microns^2) | B8: 1687.7357
A9: Minor pore diameter (microns) | B9: 6.0362576
A10: Maximum pore diameter (microns) | B10: 659.9636
A11: Mean pore diameter (microns) | B11: 35.091259
A12: Minor pore radius (microns) | B12: 3.0181288
A13: Maximum pore radius (microns) | B13: 329.9818
A14: Mean pore radius (microns) | B14: 17.54563
... A17: Mean pore perimeter (microns) | B17: 42.25683
A18: Porosity (%) | B18: 2.9305503 | C18: Fraction:
A19: Microcroporosity (%) (Anselmetti et al., 1998) | B19: 0.058864166 | C19: =B19/B18 -> 0.020086387
A20: Macro-mesoporosity (%) (Anselmetti et al., 1998) | B20: 2.8716861 | C20: =B20/B18 -> 0.97991361
A21: Mean Pore area Microporosity (microns^2)(Anselmetti et al., 1998) | B21: 230.45625
A22: Mean Pore area Macro-mesoporosity (microns^2) (Anselmetti et al., 1998) | B22: 2994.0911
A23: Mean Pore perimeter Microporosity (microns) (Anselmetti et al., 1998) | B23: 21.771192
A24: Mean Pore perimeter Macro-mesoporosity (microns) (Anselmetti et al., 1998) | B24: 60.620861
A25: Mean Pore radius Microporosity(microns) (Anselmetti et al., 1998) | B25: 8.2100146
A26: Mean Pore radius Macro-mesoporosity(microns) (Anselmetti et al., 1998) | B26: 25.914396
A27: Mean Gamma | B27: 0.40342699
A28: Mean Gamma Microporosity (Anselmetti et al., 1998) | B28: 0.42562431
A29: Mean Gamma Macro-mesoporosity (Anselmetti et al., 1998) | B29: 0.38352855
A30: Mean Fps (microns^-1) (equal to gamma^2) | B30: 0.16275334
A31: Mean Fps Microporosity (microns^-1) (Anselmetti et al., 1998) (microns^-1) | B31: 0.18115605
A32: Mean Fps Macro-mesoporosity (microns^-1) (Anselmetti et al., 1998) (microns^-1) | B32: 0.14709415
... A39: Permeability (Kozeny-Carman) (mD) | B39: 660.21931
A40: Porosity area occurence (Anselmetti et al., 1998): | B40: %
A41: <0.5 | B41: 0
A42: 0.5:5 | B42: 0
A43: 5:5E1 | B43: 9.5338844e-05
A44: 5E1:5E2 | B44: 0.058768827
A45: 5E2:5E3 | B45: 0.81398293
A46: 5E3:5E4 | B46: 1.5248234
A47: >5E4 | B47: 0.53287975
A48: Mean Aspect Ratio | B48: 0.53778411
...

Sheet F2859H
A1: F2859H
A2: LOCAL PORE PARAMETERS
A3: Pixel resolution (microns) | B3: 1.27
A4: Minimum pixel quantity for pore area | B4: 2
A5: Pore area resolution (microns^2) | B5: 6.4516
A6: Minor pore area (microns^2) | B6: 25.822136
A7: Maximum pore area (microns^2) | B7: 173392.68
A8: Mean pore area (microns^2) | B8: 1547.3827
A9: Minor pore diameter (microns) | B9: 5.7339135
A10: Maximum pore diameter (microns) | B10: 469.86213
A11: Mean pore diameter (microns) | B11: 35.009158
A12: Minor pore radius (microns) | B12: 2.8669568
A13: Maximum pore radius (microns) | B13: 234.93106
A14: Mean pore radius (microns) | B14: 17.504579
... A17: Mean pore perimeter (microns) | B17: 42.153549
A18: Porosity (%) | B18: 3.7995999 | C18: Fraction:
A19: Microcroporosity (%) (Anselmetti et al., 1998) | B19: 0.093082308 | C19: =B19/B18 -> 0.024497923
A20: Macro-mesoporosity (%) (Anselmetti et al., 1998) | B20: 3.7065176 | C20: =B20/B18 -> 0.97550208
A21: Mean Pore area Microporosity (microns^2)(Anselmetti et al., 1998) | B21: 231.8911
A22: Mean Pore area Macro-mesoporosity (microns^2) (Anselmetti et al., 1998) | B22: 2634.6243
A23: Mean Pore perimeter Microporosity (microns) (Anselmetti et al., 1998) | B23: 21.84378
A24: Mean Pore perimeter Macro-mesoporosity (microns) (Anselmetti et al., 1998) | B24: 58.939385
A25: Mean Pore radius Microporosity(microns) (Anselmetti et al., 1998) | B25: 8.2328083
A26: Mean Pore radius Macro-mesoporosity(microns) (Anselmetti et al., 1998) | B26: 25.167611
A27: Mean Gamma | B27: 0.40196309
A28: Mean Gamma Microporosity (Anselmetti et al., 1998) | B28: 0.42622599
A29: Mean Gamma Macro-mesoporosity (Anselmetti et al., 1998) | B29: 0.38191004
A30: Mean Fps (microns^-1) (equal to gamma^2) | B30: 0.16157433
A31: Mean Fps Microporosity (microns^-1) (Anselmetti et al., 1998) (microns^-1) | B31: 0.18166859
A32: Mean Fps Macro-mesoporosity (microns^-1) (Anselmetti et al., 1998) (microns^-1) | B32: 0.14585528
... A39: Permeability (Kozeny-Carman) (mD) | B39: 892.48531
A40: Porosity area occurence (Anselmetti et al., 1998): | B40: %
A41: <0.5 | B41: 0
A42: 0.5:5 | B42: 0
A43: 5:5E1 | B43: 0.00017555394
A44: 5E1:5E2 | B44: 0.092906754
A45: 5E2:5E3 | B45: 1.4059916
A46: 5E3:5E4 | B46: 1.9686539
A47: >5E4 | B47: 0.33187219
A48: Mean Aspect Ratio | B48: 0.53727093
...

Sheet F2880H
A1: F2880H
A2: LOCAL PORE PARAMETERS
A3: Pixel resolution (microns) | B3: 1.27
A4: Minimum pixel quantity for pore area | B4: 2
A5: Pore area resolution (microns^2) | B5: 6.4516
A6: Minor pore area (microns^2) | B6: 25.822136
A7: Maximum pore area (microns^2) | B7: 280403.43
A8: Mean pore area (microns^2) | B8: 687.09267
A9: Minor pore diameter (microns) | B9: 5.7339135
A10: Maximum pore diameter (microns) | B10: 597.51213
A11: Mean pore diameter (microns) | B11: 24.658906
A12: Minor pore radius (microns) | B12: 2.8669568
A13: Maximum pore radius (microns) | B13: 298.75606
A14: Mean pore radius (microns) | B14: 12.329453
... A17: Mean pore perimeter (microns) | B17: 30.51615
A18: Porosity (%) | B18: 9.1346953 | C18: Fraction:
A19: Microcroporosity (%) (Anselmetti et al., 1998) | B19: 0.87537613 | C19: =B19/B18 -> 0.095829811
A20: Macro-mesoporosity (%) (Anselmetti et al., 1998) | B20: 8.2593192 | C20: =B20/B18 -> 0.90417019
A21: Mean Pore area Microporosity (microns^2)(Anselmetti et al., 1998) | B21: 210.49391
A22: Mean Pore area Macro-mesoporosity (microns^2) (Anselmetti et al., 1998) | B22: 1509.1799
A23: Mean Pore perimeter Microporosity (microns) (Anselmetti et al., 1998) | B23: 20.53128
A24: Mean Pore perimeter Macro-mesoporosity (microns) (Anselmetti et al., 1998) | B24: 47.739093
A25: Mean Pore radius Microporosity(microns) (Anselmetti et al., 1998) | B25: 7.8040432
A26: Mean Pore radius Macro-mesoporosity(microns) (Anselmetti et al., 1998) | B26: 20.135351
A27: Mean Gamma | B27: 0.40849057
A28: Mean Gamma Microporosity (Anselmetti et al., 1998) | B28: 0.4233885
A29: Mean Gamma Macro-mesoporosity (Anselmetti et al., 1998) | B29: 0.38279306
A30: Mean Fps (microns^-1) (equal to gamma^2) | B30: 0.16686454
A31: Mean Fps Microporosity (microns^-1) (Anselmetti et al., 1998) (microns^-1) | B31: 0.17925782
A32: Mean Fps Macro-mesoporosity (microns^-1) (Anselmetti et al., 1998) (microns^-1) | B32: 0.14653053
... A39: Permeability (Kozeny-Carman) (mD) | B39: 1313.476
A40: Porosity area occurence (Anselmetti et al., 1998): | B40: %
A41: <0.5 | B41: 0
A42: 0.5:5 | B42: 0
A43: 5:5E1 | B43: 0.0025487898
A44: 5E1:5E2 | B44: 0.87282734
A45: 5E2:5E3 | B45: 5.4803081
A46: 5E3:5E4 | B46: 2.4738065
A47: >5E4 | B47: 0.30520454
A48: Mean Aspect Ratio | B48: 0.56029398
...

Sheet F2910H
A1: F2910H
A2: LOCAL PORE PARAMETERS
A3: Pixel resolution (microns) | B3: 1.27
A4: Minimum pixel quantity for pore area | B4: 2
A5: Pore area resolution (microns^2) | B5: 6.4516
A6: Minor pore area (microns^2) | B6: 25.822136
A7: Maximum pore area (microns^2) | B7: 2982101.3
A8: Mean pore area (microns^2) | B8: 811.45992
A9: Minor pore diameter (microns) | B9: 5.7339135
A10: Maximum pore diameter (microns) | B10: 1948.5711
A11: Mean pore diameter (microns) | B11: 24.789151
A12: Minor pore radius (microns) | B12: 2.8669568
A13: Maximum pore radius (microns) | B13: 974.28554
A14: Mean pore radius (microns) | B14: 12.394575
... A17: Mean pore perimeter (microns) | B17: 30.141897
A18: Porosity (%) | B18: 8.6931056 | C18: Fraction:
A19: Microcroporosity (%) (Anselmetti et al., 1998) | B19: 0.59316557 | C19: =B19/B18 -> 0.068234023
A20: Macro-mesoporosity (%) (Anselmetti et al., 1998) | B20: 8.09994 | C20: =B20/B18 -> 0.93176598
A21: Mean Pore area Microporosity (microns^2)(Anselmetti et al., 1998) | B21: 198.44515
A22: Mean Pore area Macro-mesoporosity (microns^2) (Anselmetti et al., 1998) | B22: 2062.1909
A23: Mean Pore perimeter Microporosity (microns) (Anselmetti et al., 1998) | B23: 20.025878
A24: Mean Pore perimeter Macro-mesoporosity (microns) (Anselmetti et al., 1998) | B24: 50.781559
A25: Mean Pore radius Microporosity(microns) (Anselmetti et al., 1998) | B25: 7.56296
A26: Mean Pore radius Macro-mesoporosity(microns) (Anselmetti et al., 1998) | B26: 22.252496
A27: Mean Gamma | B27: 0.40890548
A28: Mean Gamma Microporosity (Anselmetti et al., 1998) | B28: 0.42672468
A29: Mean Gamma Macro-mesoporosity (Anselmetti et al., 1998) | B29: 0.37254907
A30: Mean Fps (microns^-1) (equal to gamma^2) | B30: 0.16720369
A31: Mean Fps Microporosity (microns^-1) (Anselmetti et al., 1998) (microns^-1) | B31: 0.18209395
A32: Mean Fps Macro-mesoporosity (microns^-1) (Anselmetti et al., 1998) (microns^-1) | B32: 0.13879281
... A39: Permeability (Kozeny-Carman) (mD) | B39: 1112.1689
A40: Porosity area occurence (Anselmetti et al., 1998): | B40: %
A41: <0.5 | B41: 0
A42: 0.5:5 | B42: 0
A43: 5:5E1 | B43: 0.0022605713
A44: 5E1:5E2 | B44: 0.59090499
A45: 5E2:5E3 | B45: 3.2975978
A46: 5E3:5E4 | B46: 3.6525065
A47: >5E4 | B47: 1.1498357
A48: Mean Aspect Ratio | B48: 0.56924221
...

Sheet F2911V
A1: F2911V
A2: LOCAL PORE PARAMETERS
A3: Pixel resolution (microns) | B3: 1.27
A4: Minimum pixel quantity for pore area | B4: 2
A5: Pore area resolution (microns^2) | B5: 6.4516
A6: Minor pore area (microns^2) | B6: 25.822136
A7: Maximum pore area (microns^2) | B7: 705065.97
A8: Mean pore area (microns^2) | B8: 772.34153
A9: Minor pore diameter (microns) | B9: 5.7339135
A10: Maximum pore diameter (microns) | B10: 947.47975
A11: Mean pore diameter (microns) | B11: 25.007331
A12: Minor pore radius (microns) | B12: 2.8669568
A13: Maximum pore radius (microns) | B13: 473.73987
A14: Mean pore radius (microns) | B14: 12.503666
... A17: Mean pore perimeter (microns) | B17: 30.630387
A18: Porosity (%) | B18: 11.318632 | C18: Fraction:
A19: Microcroporosity (%) (Anselmetti et al., 1998) | B19: 0.82644777 | C19: =B19/B18 -> 0.073016581
A20: Macro-mesoporosity (%) (Anselmetti et al., 1998) | B20: 10.492184 | C20: =B20/B18 -> 0.92698342
A21: Mean Pore area Microporosity (microns^2)(Anselmetti et al., 1998) | B21: 205.53405
A22: Mean Pore area Macro-mesoporosity (microns^2) (Anselmetti et al., 1998) | B22: 1818.5043
A23: Mean Pore perimeter Microporosity (microns) (Anselmetti et al., 1998) | B23: 20.118323
A24: Mean Pore perimeter Macro-mesoporosity (microns) (Anselmetti et al., 1998) | B24: 50.032618
A25: Mean Pore radius Microporosity(microns) (Anselmetti et al., 1998) | B25: 7.7138876
A26: Mean Pore radius Macro-mesoporosity(microns) (Anselmetti et al., 1998) | B26: 21.344211
A27: Mean Gamma | B27: 0.40572047
A28: Mean Gamma Microporosity (Anselmetti et al., 1998) | B28: 0.41969281
A29: Mean Gamma Macro-mesoporosity (Anselmetti et al., 1998) | B29: 0.37993158
A30: Mean Fps (microns^-1) (equal to gamma^2) | B30: 0.1646091
A31: Mean Fps Microporosity (microns^-1) (Anselmetti et al., 1998) (microns^-1) | B31: 0.17614205
A32: Mean Fps Macro-mesoporosity (microns^-1) (Anselmetti et al., 1998) (microns^-1) | B32: 0.14434801
... A39: Permeability (Kozeny-Carman) (mD) | B39: 1602.5696
A40: Porosity area occurence (Anselmetti et al., 1998): | B40: %
A41: <0.5 | B41: 0
A42: 0.5:5 | B42: 0
A43: 5:5E1 | B43: 0.0023676221
A44: 5E1:5E2 | B44: 0.82408015
A45: 5E2:5E3 | B45: 5.3036508
A46: 5E3:5E4 | B46: 3.9823164
A47: >5E4 | B47: 1.2062165
A48: Mean Aspect Ratio | B48: 0.54715049
...

Sheet F2935H
A1: F2935H
A2: LOCAL PORE PARAMETERS
A3: Pixel resolution (microns) | B3: 1.27
A4: Minimum pixel quantity for pore area | B4: 2
A5: Pore area resolution (microns^2) | B5: 6.4516
A6: Minor pore area (microns^2) | B6: 25.822136
A7: Maximum pore area (microns^2) | B7: 1052435
A8: Mean pore area (microns^2) | B8: 796.95724
A9: Minor pore diameter (microns) | B9: 5.7339135
A10: Maximum pore diameter (microns) | B10: 1157.5845
A11: Mean pore diameter (microns) | B11: 24.75381
A12: Minor pore radius (microns) | B12: 2.8669568
A13: Maximum pore radius (microns) | B13: 578.79226
A14: Mean pore radius (microns) | B14: 12.376905
... A17: Mean pore perimeter (microns) | B17: 30.31975
A18: Porosity (%) | B18: 13.70362 | C18: Fraction:
A19: Microcroporosity (%) (Anselmetti et al., 1998) | B19: 0.98194549 | C19: =B19/B18 -> 0.071655921
A20: Macro-mesoporosity (%) (Anselmetti et al., 1998) | B20: 12.721674 | C20: =B20/B18 -> 0.92834408
A21: Mean Pore area Microporosity (microns^2)(Anselmetti et al., 1998) | B21: 204.81009
A22: Mean Pore area Macro-mesoporosity (microns^2) (Anselmetti et al., 1998) | B22: 2085.4882
A23: Mean Pore perimeter Microporosity (microns) (Anselmetti et al., 1998) | B23: 20.123719
A24: Mean Pore perimeter Macro-mesoporosity (microns) (Anselmetti et al., 1998) | B24: 52.506637
A25: Mean Pore radius Microporosity(microns) (Anselmetti et al., 1998) | B25: 7.7097187
A26: Mean Pore radius Macro-mesoporosity(microns) (Anselmetti et al., 1998) | B26: 22.53285
A27: Mean Gamma | B27: 0.40700371
A28: Mean Gamma Microporosity (Anselmetti et al., 1998) | B28: 0.41995715
A29: Mean Gamma Macro-mesoporosity (Anselmetti et al., 1998) | B29: 0.37881661
A30: Mean Fps (microns^-1) (equal to gamma^2) | B30: 0.16565202
A31: Mean Fps Microporosity (microns^-1) (Anselmetti et al., 1998) (microns^-1) | B31: 0.17636401
A32: Mean Fps Macro-mesoporosity (microns^-1) (Anselmetti et al., 1998) (microns^-1) | B32: 0.14350202
... A39: Permeability (Kozeny-Carman) (mD) | B39: 1841.816
A40: Porosity area occurence (Anselmetti et al., 1998): | B40: %
A41: <0.5 | B41: 0
A42: 0.5:5 | B42: 0
A43: 5:5E1 | B43: 0.0026446871
A44: 5E1:5E2 | B44: 0.9793008
A45: 5E2:5E3 | B45: 5.6283702
A46: 5E3:5E4 | B46: 5.8716376
A47: >5E4 | B47: 1.2216663
A48: Mean Aspect Ratio | B48: 0.55726415
...

Sheet F2870H
A1: F2870H(6mm)
A2: LOCAL PORE PARAMETERS
A3: Pixel resolution (microns) | B3: 3.33
A4: Minimum pixel quantity for pore area | B4: 2
A5: Pore area resolution (microns^2) | B5: 44.3556
A6: Minor pore area (microns^2) | B6: 177.53059
A7: Maximum pore area (microns^2) | B7: 188673.67
A8: Mean pore area (microns^2) | B8: 2746.456
A9: Minor pore diameter (microns) | B9: 15.034592
A10: Maximum pore diameter (microns) | B10: 490.12935
A11: Mean pore diameter (microns) | B11: 51.217537
A12: Minor pore radius (microns) | B12: 7.5172961
A13: Maximum pore radius (microns) | B13: 245.06467
A14: Mean pore radius (microns) | B14: 25.608769
... A17: Mean pore perimeter (microns) | B17: 64.004879
A18: Porosity (%) | B18: 0.37049279 | C18: Fraction:
A19: Microcroporosity (%) (Anselmetti et al., 1998) | B19: 0.0019874236 | C19: =B19/B18 -> 0.0053642707
A20: Macro-mesoporosity (%) (Anselmetti et al., 1998) | B20: 0.36850536 | C20: =B20/B18 -> 0.99463573
A21: Mean Pore area Microporosity (microns^2)(Anselmetti et al., 1998) | B21: 401.58269
A22: Mean Pore area Macro-mesoporosity (microns^2) (Anselmetti et al., 1998) | B22: 3005.4263
A23: Mean Pore perimeter Microporosity (microns) (Anselmetti et al., 1998) | B23: 31.994744
A24: Mean Pore perimeter Macro-mesoporosity (microns) (Anselmetti et al., 1998) | B24: 67.540112
A25: Mean Pore radius Microporosity(microns) (Anselmetti et al., 1998) | B25: 11.263885
A26: Mean Pore radius Macro-mesoporosity(microns) (Anselmetti et al., 1998) | B26: 27.193033
A27: Mean Gamma | B27: 0.40957173
A28: Mean Gamma Microporosity (Anselmetti et al., 1998) | B28: 0.45305849
A29: Mean Gamma Macro-mesoporosity (Anselmetti et al., 1998) | B29: 0.404769
A30: Mean Fps (microns^-1) (equal to gamma^2) | B30: 0.167749
A31: Mean Fps Microporosity (microns^-1) (Anselmetti et al., 1998) (microns^-1) | B31: 0.205262
A32: Mean Fps Macro-mesoporosity (microns^-1) (Anselmetti et al., 1998) (microns^-1) | B32: 0.16383795
... A39: Permeability (Kozeny-Carman) (mD) | B39: 270.33302
A40: Porosity area occurence (Anselmetti et al., 1998): | B40: %
A41: <0.5 | B41: 0
A42: 0.5:5 | B42: 0
A43: 5:5E1 | B43: 0
A44: 5E1:5E2 | B44: 0.0019874236
A45: 5E2:5E3 | B45: 0.12448357
A46: 5E3:5E4 | B46: 0.21863164
A47: >5E4 | B47: 0.025390158
A48: Mean Aspect Ratio | B48: 0.55125387
...
