Workbook

Sheet General Information
A8: LENEP | B8: Petroleum Exploration and Enginnering Lab
A9: Coordinator | B9: Prof. Marco Ceia
A10: Contact | B10: marco@lenep.uenf.br
A13: Abbreviations & Symbols
A14: K[N2] | B14: Nitrogen Gas Permeability
A15: Vp | B15: P wave velocity
A16: Vs | B16: S wave velocity
A17: FPS | B17: Frames per second
A18: Cpc | B18: Pore compressibility
A19: Cbc | B19: Bulk compressibility
A20: Pc | B20: Confining Pressure
A21: Kdry | B21: Bulk modulus of the dry rock
A22: Kmin | B22: Mineral bulk Modulus
A23: Coef. Biot | B23: Biot Coefficient
A24: Kg | B24: Permeability (Coreval)
A25: ϕ | B25: Porosity (Coreval)
A31: BFW Brine
A32: Salt | B32: Name | C32: Concentration (g/L) | D32: Concentration (g/2L) | E32: Concentration (g/5L)
A33: NaCl | B33: Sodium chloride | C33: 146.32 | D33: 292.64 | E33: 731.59
A34: KCl | B34: Potassium chloride | C34: 2.288 | D34: 4.58 | E34: 11.44
A35: CaCl2.2H2O | B35: Calcium chloride dihydrate | C35: 88.77 | D35: 177.54 | E35: 443.85
A36: MgCl2.6H20 | B36: Magnesium chloride hexahydrate | C36: 17.72 | D36: 35.45 | E36: 88.62
A37: BaCl2.2H2O | B37: Barium chloride dihydrate | C37: 0.04 | D37: 0.09 | E37: 0.21
A38: SrCl2.6H2O | B38: Strontium chloride hexahydrate | C38: 3.833 | D38: 7.67 | E38: 19.16
A39: Na2SO4 | B39: Sodium sulfate | C39: 0.06 | D39: 0.12 | E39: 0.3

Sheet Rock info
A2: Sample | B2: Thin Section | C2: Depth (m) | D2: Geological Age | E2: Location | F2: Well | G2: Classification | H2: Main Pore Types | I2: Sample Type | J2: Source Table | K2: Dry Weight (g) | L2: Caliper Bulk Volume (cm³) | M2: Observation
A3: F7285V | B3: 7285V | C3: 5054.2 | D3: Aptian | E3: Santos Basin, Barra Velha Fm. | F3: BR 1-BRSA-1045-SPS | G3: Grainstone | H3: Vug, intraparticle | I3: Well plug | J3: LENEP - UENF | K3: 123097 | L3: 47057
A4: F7286H | B4: 7187-1 | C4: 5054.3 | D4: Aptian | E4: Santos Basin, Barra Velha Fm. | F4: BR 1-BRSA-1045-SPS | G4: Grainstone | H4: Fracture, channel, and vugs. | I4: Well plug | J4: LENEP - UENF | K4: 141297 | L4: 51275
A5: F7287H | B5: 71880-1 | C5: 5054.55 | D5: Aptian | E5: Santos Basin, Barra Velha Fm. | F5: BR 1-BRSA-1045-SPS | G5: Grainstone | H5: Vug | I5: Well plug | J5: LENEP - UENF | K5: 136322 | L5: 57808
A6: F7288H | B6: 7189-1 | C6: 5054.8 | D6: Aptian | E6: Santos Basin, Barra Velha Fm. | F6: BR 1-BRSA-1045-SPS | G6: Grainstone | H6: Channel, vugs, and intraparticle. | I6: Well plug | J6: LENEP - UENF | K6: 119558 | L6: 49901
A7: - | B7: 4587-1 | C7: 5055 | D7: Aptian | E7: Santos Basin, Barra Velha Fm. | F7: BR 1-BRSA-1045-SPS
A8: F7289H | B8: 7190-1 | C8: 5055.1 | D8: Aptian | E8: Santos Basin, Barra Velha Fm. | F8: BR 1-BRSA-1045-SPS | G8: Grainstone with calcite spherulitic, fragments of shrubs, and peloids. | H8: Interparticle,vugs, and channels. | I8: Well plug | J8: LENEP - UENF | K8: 145.474 | L8: 61.561
A9: F7290V | B9: 7290V | C9: 5055.2 | D9: Aptian | E9: Santos Basin, Barra Velha Fm. | F9: BR 1-BRSA-1045-SPS | G9: Grainstone | H9: Intraparticle, interparticle, and vugs. | I9: Well plug | J9: LENEP - UENF | K9: 198.802 | L9: 84.034
A10: F7291H | B10: 7191-1 | C10: 5055.4 | D10: Aptian | E10: Santos Basin, Barra Velha Fm. | F10: BR 1-BRSA-1045-SPS | G10: Silexite | H10: vugs, intraparticles and vugs. | I10: Well plug | J10: LENEP - UENF | K10: 148.161 | L10: 59.293 | M10: Oil Impregnated
A11: F7292H | B11: 7192-1 | C11: 5055.75 | D11: Aptian | E11: Santos Basin, Barra Velha Fm. | F11: BR 1-BRSA-1045-SPS | G11: Grainstone with spherulites, shrubs fragments, and, peloids. | H11: Channel, vugs, and intraparticle. | I11: Well plug | J11: LENEP - UENF | K11: 137.392 | L11: 59.824
A12: F7293H | B12: 7193-2 | C12: 5056.1 | D12: Aptian | E12: Santos Basin, Barra Velha Fm. | F12: BR 1-BRSA-1045-SPS | G12: Grainstone with shrubs fragments, and, peloids. | H12: Intraparticle , interparticle | I12: Well plug | J12: LENEP - UENF | K12: 130.187 | L12: 54.752
A13: F7294H | B13: 7194-1 | C13: 5056.4 | D13: Aptian | E13: Santos Basin, Barra Velha Fm. | F13: BR 1-BRSA-1045-SPS | G13: Grainstone with shrubs fragments, spherulites and, peloids | H13: intercrystal, intraparticles, vugs, breccias, and channels | I13: Well plug | J13: LENEP - UENF | K13: 135.455 | L13: 60.557
A14: F7295V | B14: 7295V | C14: 5056.5 | D14: Aptian | E14: Santos Basin, Barra Velha Fm. | F14: BR 1-BRSA-1045-SPS | G14: Grainstone | H14: Vugs, interparticle, and channels. | I14: Well plug | J14: LENEP - UENF | K14: 197.743 | L14: 85.243
A15: F7296H | B15: 7391-1 | C15: 5056.65 | D15: Aptian | E15: Santos Basin, Barra Velha Fm. | F15: BR 1-BRSA-1045-SPS | G15: Arborescent shrub | H15: Intraparticle and moldic. | I15: Well plug | J15: LENEP - UENF | K15: 142.992 | L15: 59.062
A16: F7297H | B16: 7196-1 | C16: 5056.95 | D16: Aptian | E16: Santos Basin, Barra Velha Fm. | F16: BR 1-BRSA-1045-SPS | G16: Arborescent shrub | H16: Vug, fracture, and channels. | I16: Well plug | J16: LENEP - UENF | K16: 124.512 | L16: 51.116
A17: F2829V | C17: 5206 | D17: Aptian | E17: Santos Basin, Barra Velha Fm. | F17: BR 3-BRSA-861-SPS | I17: Well plug | J17: LENEP - UENF | K17: 172.696 | L17: 69.094
A18: F2830H | C18: 5206.05 | D18: Aptian | E18: Santos Basin, Barra Velha Fm. | F18: BR 3-BRSA-861-SPS | I18: Well plug | J18: LENEP - UENF | K18: 182.26 | L18: 70.898
A19: F2846H | C19: 5210.05 | D19: Aptian | E19: Santos Basin, Barra Velha Fm. | F19: BR 3-BRSA-861-SPS | I19: Well plug | J19: LENEP - UENF | K19: 171.805 | L19: 72.255
A20: F2852H | C20: 5211.4 | D20: Aptian | E20: Santos Basin, Barra Velha Fm. | F20: BR 3-BRSA-861-SPS | I20: Well plug | J20: LENEP - UENF | K20: 206.63 | L20: 77.496
A21: F2853H | C21: 5211.8 | D21: Aptian | E21: Santos Basin, Barra Velha Fm. | F21: BR 3-BRSA-861-SPS | I21: Well plug | J21: LENEP - UENF | K21: 142.651 | L21: 54.307
A22: F2854H | C22: 5212.05 | D22: Aptian | E22: Santos Basin, Barra Velha Fm. | F22: BR 3-BRSA-861-SPS | I22: Well plug | J22: LENEP - UENF | K22: 191.347 | L22: 76.769
A23: F2855V | C23: 5212.15 | D23: Aptian | E23: Santos Basin, Barra Velha Fm. | F23: BR 3-BRSA-861-SPS | I23: Well plug | J23: LENEP - UENF | K23: 189.453 | L23: 77.56
A24: F2857H | C24: 5212.7 | D24: Aptian | E24: Santos Basin, Barra Velha Fm. | F24: BR 3-BRSA-861-SPS | I24: Well plug | J24: LENEP - UENF | K24: 200.884 | L24: 78.072
A25: F2858V | C25: 5212.75 | D25: Aptian | E25: Santos Basin, Barra Velha Fm. | F25: BR 3-BRSA-861-SPS | I25: Well plug | J25: LENEP - UENF | K25: 139.365 | L25: 55.4
A26: F2859H | C26: 5212.9 | D26: Aptian | E26: Santos Basin, Barra Velha Fm. | F26: BR 3-BRSA-861-SPS | I26: Well plug | J26: LENEP - UENF | K26: 195.012 | L26: 77.079
A27: F2868H | C27: 5215.2 | D27: Aptian | E27: Santos Basin, Barra Velha Fm. | F27: BR 3-BRSA-861-SPS | I27: Well plug | J27: LENEP - UENF | K27: 183.718 | L27: 76.616
A28: F2870H | C28: 5215.55 | D28: Aptian | E28: Santos Basin, Barra Velha Fm. | F28: BR 3-BRSA-861-SPS | I28: Well plug | J28: LENEP - UENF | K28: 181.088 | L28: 70.867
... A45: F2936H | C45: 5232.55 | D45: Aptian | E45: Santos Basin, Barra Velha Fm. | F45: BR 3-BRSA-861-SPS | I45: Well plug | J45: LENEP - UENF | K45: 173.54 | L45: 66.259
A46: COD-SA-01-AH | B46: 3586 | D46: Aptian | E46: Codó Fm., Parnaíba Basin | G46: Grainstone | I46: Outcrop | J46: LENEP - UENF | K46: 187.661 | L46: 73.614
A47: COD-SA-01-AV | B47: 3590 | D47: Aptian | E47: Codó Fm., Parnaíba Basin | G47: Grainstone | I47: Outcrop | J47: LENEP - UENF | K47: 173.233 | L47: 68.089
A48: COD-SA-01-BH | D48: Aptian | E48: Codó Fm., Parnaíba Basin | I48: Outcrop | J48: LENEP - UENF | K48: 157.606 | L48: 62.53
A49: COD-SA-01-BV | B49: 3589 | D49: Aptian | E49: Codó Fm., Parnaíba Basin | G49: Grainstone | I49: Outcrop | J49: LENEP - UENF | K49: 172.829 | L49: 68.136
A50: COD-SA-01-CH | B50: 3587 | D50: Aptian | E50: Codó Fm., Parnaíba Basin | G50: Grainstone | I50: Outcrop | J50: LENEP - UENF | K50: 155.168 | L50: 60.982
A51: COD-SA-01-CV | D51: Aptian | E51: Codó Fm., Parnaíba Basin | I51: Outcrop | J51: LENEP - UENF | K51: 172.14 | L51: 68.495
A52: COD-SA-01-DH | D52: Aptian | E52: Codó Fm., Parnaíba Basin | I52: Outcrop | J52: LENEP - UENF | K52: 129.464 | L52: 49.471
A53: COD-SA-01-DV | D53: Aptian | E53: Codó Fm., Parnaíba Basin | I53: Outcrop | J53: LENEP - UENF | K53: 157.85 | L53: 66.76
A54: COD-AS-01-EH | B54: 3591 | D54: Aptian | E54: Codó Fm., Parnaíba Basin | G54: Grainstone | I54: Outcrop | J54: LENEP - UENF
A55: COD-AS-01-EV | B55: 3592 | D55: Aptian | E55: Codó Fm., Parnaíba Basin | G55: Grainstone | I55: Outcrop | J55: LENEP - UENF
A56: COD-AS-01-FH | B56: 3588 | D56: Aptian | E56: Codó Fm., Parnaíba Basin | G56: Grainstone | I56: Outcrop | J56: LENEP - UENF | K56: 188.871 | L56: 77.375
A57: GRA-BAR-01-AH | B57: 3593 | D57: Aptian | E57: Codó Fm., Parnaíba Basin | G57: Mudstone | I57: Outcrop | J57: LENEP - UENF | K57: 143.913 | L57: 63.06
...

Sheet Porosity
A2: Sample | B2: Depth (m) | C2: Well / Location | D2: Unconfined Porosity (%) | E2: Bulk Density (dry) (g/cm³) | F2: Grain Density (g/cm³) | G2: Observation
A3: F7285V | B3: 5054.2 | C3: BR 1-BRSA-1045-SPS | D3: 5.257 | E3: 2.616 | F3: 2.761 | G3: Estimated from XRD and 3D Scanner info
A4: F7286H | B4: 5054.3 | C4: BR 1-BRSA-1045-SPS | D4: 3.885 | E4: 2.756 | F4: 2.867 | G4: Estimated from XRD and 3D Scanner info
A5: F7287H | B5: 5054.55 | C5: BR 1-BRSA-1045-SPS | D5: 13.435 | E5: 2.358 | F5: 2.724 | G5: Estimated from XRD and 3D Scanner info
A6: F7288H | B6: 5054.8 | C6: BR 1-BRSA-1045-SPS | D6: 12.404 | E6: 2.396 | F6: 2.735 | G6: Estimated from XRD and 3D Scanner info
A7: F7289H | B7: 5055.1 | C7: BR 1-BRSA-1045-SPS | D7: 12.735 | E7: ='Rock info'!K8/'Rock info'!L8 -> 2.363087 | F7: 2.708 | G7: Ultrapore 300 - Gas Porosity
A8: F7290V | B8: 5055.2 | C8: BR 1-BRSA-1045-SPS | D8: 13.818 | E8: ='Rock info'!K9/'Rock info'!L9 -> 2.3657329 | F8: 2.745 | G8: Ultrapore 300 - Gas Porosity
A9: F7291H | B9: 5055.4 | C9: BR 1-BRSA-1045-SPS | D9: 6.776 | E9: ='Rock info'!K10/'Rock info'!L10 -> 2.4987941 | F9: 2.6802 | G9: Ultrapore 300 - Gas Porosity
A10: F7292H | B10: 5055.75 | C10: BR 1-BRSA-1045-SPS | D10: 16.219 | E10: ='Rock info'!K11/'Rock info'!L11 -> 2.2966034 | F10: 2.7414 | G10: Ultrapore 300 - Gas Porosity
A11: F7293H | B11: 5056.1 | C11: BR 1-BRSA-1045-SPS | D11: 12.569 | E11: ='Rock info'!K12/'Rock info'!L12 -> 2.3777579 | F11: 2.7198 | G11: Ultrapore 300 - Gas Porosity
A12: F7294H | B12: 5056.4 | C12: BR 1-BRSA-1045-SPS | D12: 18.114 | E12: ='Rock info'!K13/'Rock info'!L13 -> 2.2368182 | F12: 2.7318 | G12: Ultrapore 300 - Gas Porosity
A13: F7295V | B13: 5056.5 | C13: BR 1-BRSA-1045-SPS | D13: 16.009 | E13: ='Rock info'!K14/'Rock info'!L14 -> 2.3197565 | F13: 2.762 | G13: Ultrapore 300 - Gas Porosity
A14: F7296H | B14: 5056.65 | C14: BR 1-BRSA-1045-SPS | D14: 10.541 | E14: ='Rock info'!K15/'Rock info'!L15 -> 2.4210491 | F14: 2.7066 | G14: Ultrapore 300 - Gas Porosity
A15: F7297H | B15: 5056.95 | C15: BR 1-BRSA-1045-SPS | D15: 9.654 | E15: ='Rock info'!K16/'Rock info'!L16 -> 2.4358714 | F15: 2.6962 | G15: Ultrapore 300 - Gas Porosity
A16: F2829V | B16: 5206 | C16: BR 3-BRSA-861-SPS | D16: 6.723 | E16: 2.4994356 | F16: 2.68 | G16: Ultrapore 300 - Gas Porosity
A17: F2830H | B17: 5206.05 | C17: BR 3-BRSA-861-SPS | D17: 3.782 | E17: 2.5707354 | F17: 2.672 | G17: Ultrapore 300 - Gas Porosity
A18: F2846H | B18: 5210.05 | C18: BR 3-BRSA-861-SPS | D18: 9.32 | E18: 2.3777593 | F18: 2.622 | G18: Ultrapore 300 - Gas Porosity
A19: F2852H | B19: 5211.4 | C19: BR 3-BRSA-861-SPS | D19: 1.328 | E19: 2.6663312 | F19: 2.702 | G19: Ultrapore 300 - Gas Porosity
A20: F2853H | B20: 5211.8 | C20: BR 3-BRSA-861-SPS | D20: 2.761 | E20: 2.6267516 | F20: 2.701 | G20: Ultrapore 300 - Gas Porosity
A21: F2854H | B21: 5212.05 | C21: BR 3-BRSA-861-SPS | D21: 8.028 | E21: 2.4925035 | F21: 2.71 | G21: Ultrapore 300 - Gas Porosity
A22: F2855V | B22: 5212.15 | C22: BR 3-BRSA-861-SPS | D22: 9.93 | E22: 2.4426637 | F22: 2.712 | G22: Ultrapore 300 - Gas Porosity
A23: F2857H | B23: 5212.7 | C23: BR 3-BRSA-861-SPS | D23: 5.584 | E23: 2.5730608 | F23: 2.725 | G23: Ultrapore 300 - Gas Porosity
A24: F2858V | B24: 5212.75 | C24: BR 3-BRSA-861-SPS | D24: 7.28 | E24: 2.5156137 | F24: 2.713 | G24: Ultrapore 300 - Gas Porosity
A25: F2859H | B25: 5212.9 | C25: BR 3-BRSA-861-SPS | D25: 6.37 | E25: 2.5300276 | F25: 2.702 | G25: Ultrapore 300 - Gas Porosity
A26: F2868H | B26: 5215.2 | C26: BR 3-BRSA-861-SPS | D26: 8.86 | E26: 2.3979064 | F26: 2.631 | G26: Ultrapore 300 - Gas Porosity
A27: F2870H | B27: 5215.55 | C27: BR 3-BRSA-861-SPS | D27: 4.461 | E27: 2.5553219 | F27: 2.675 | G27: Ultrapore 300 - Gas Porosity
... A44: F2936H | B44: 5232.55 | C44: BR 3-BRSA-861-SPS | D44: 3.846 | E44: 2.6191159 | F44: 2.724 | G44: Ultrapore 300 - Gas Porosity
A45: COD-SA-01-AH | C45: Codó Fm. | D45: 5.724 | E45: 2.5492569 | F45: 2.704 | G45: Ultrapore 300 - Gas Porosity
A46: COD-SA-01-AV | C46: Codó Fm. | D46: 6.817 | E46: 2.5442142 | F46: 2.73 | G46: Ultrapore 300 - Gas Porosity
A47: COD-SA-01-BH | C47: Codó Fm. | D47: 8.474 | E47: 2.5204862 | F47: 2.754 | G47: Ultrapore 300 - Gas Porosity
A48: COD-SA-01-BV | C48: Codó Fm. | D48: 7.154 | E48: 2.5365299 | F48: 2.732 | G48: Ultrapore 300 - Gas Porosity
A49: COD-SA-01-CH | C49: Codó Fm. | D49: 7.522 | E49: 2.5444885 | F49: 2.751 | G49: Ultrapore 300 - Gas Porosity
A50: COD-SA-01-CV | C50: Codó Fm. | D50: 7.895 | E50: 2.5131761 | F50: 2.729 | G50: Ultrapore 300 - Gas Porosity
A51: COD-SA-01-DH | C51: Codó Fm. | D51: 4.829 | E51: 2.6169675 | F51: 2.75 | G51: Ultrapore 300 - Gas Porosity
A52: COD-SA-01-DV | C52: Codó Fm. | D52: 13.245 | E52: 2.3644398 | F52: 2.725 | G52: Ultrapore 300 - Gas Porosity
A53: COD-AS-01-EH | C53: Codó Fm. | D53: 8.1797611 | E53: 2.5180002 | F53: 2.709889 | G53: Estimated from XRD and 3D Scanner info
A54: COD-AS-01-EV | C54: Codó Fm. | D54: 7.0818801 | E54: 2.4882266 | F54: 2.709913 | G54: Estimated from XRD and 3D Scanner info
A55: COD-AS-01-FH | C55: Codó Fm. | D55: 22.835 | E55: 2.4409822 | F55: 3.163 | G55: Ultrapore 300 - Gas Porosity
A56: GRA-BAR-01-AH | C56: Codó Fm. | D56: 14.994 | E56: 2.2821598 | F56: 2.685 | G56: Ultrapore 300 - Gas Porosity
... A105: Estr.cimen3 | C105: Lagoa Salgada | D105: 23.5358 | E105: 1.95 | F105: 2.544 | G105: Ultrapore 300 - Gas Porosity

Sheet Permeability
A2: Sample | B2: Depth (m) | C2: Well / Location | D2: K[n2] (mD) | E2: Klinkenberg Permeability (mD) | F2: Ambient Pressure Gas Porosity (%) | G2: Gas Porosity (%) | H2: Confining Pressure (Psi) | I2: Confining Pressure (Mpa) | J2: Permeability Method Type | K2: Observation
A3: F7289H | B3: 5055.1 | C3: BR 1-BRSA-1045-SPS | D3: 6.789339 | E3: 5.600418 | F3: 12.734732 | G3: 12.586882 | H3: 400 | I3: =H3*0.00689476 -> 2.757904 | J3: Gas-inflow | K3: LOAD
A4: F7289H | B4: 5055.1 | C4: BR 1-BRSA-1045-SPS | D4: 6.675746 | E4: 5.40038 | F4: 12.734732 | G4: 12.58157 | H4: 800 | I4: =H4*0.00689476 -> 5.515808 | J4: Gas-inflow | K4: LOAD
A5: F7289H | B5: 5055.1 | C5: BR 1-BRSA-1045-SPS | D5: 6.639046 | E5: 5.370967 | F5: 12.734732 | G5: 12.540288 | H5: 1200 | I5: =H5*0.00689476 -> 8.273712 | J5: Gas-inflow | K5: LOAD
A6: F7289H | B6: 5055.1 | C6: BR 1-BRSA-1045-SPS | D6: 6.53479 | E6: 5.328197 | F6: 12.734732 | G6: 12.510031 | H6: 1600 | I6: =H6*0.00689476 -> 11.031616 | J6: Gas-inflow | K6: LOAD
A7: F7289H | B7: 5055.1 | C7: BR 1-BRSA-1045-SPS | D7: 6.541841 | E7: 5.164422 | F7: 12.734732 | G7: 12.483936 | H7: 2000 | I7: =H7*0.00689476 -> 13.78952 | J7: Gas-inflow | K7: LOAD
A8: F7289H | B8: 5055.1 | C8: BR 1-BRSA-1045-SPS | D8: 6.430573 | E8: 5.333663 | F8: 12.734732 | G8: 12.463082 | H8: 2400 | I8: =H8*0.00689476 -> 16.547424 | J8: Gas-inflow | K8: LOAD
A9: F7289H | B9: 5055.1 | C9: BR 1-BRSA-1045-SPS | D9: 6.392771 | E9: 5.301185 | F9: 12.734732 | G9: 12.436375 | H9: 2800 | I9: =H9*0.00689476 -> 19.305328 | J9: Gas-inflow | K9: LOAD
A10: F7289H | B10: 5055.1 | C10: BR 1-BRSA-1045-SPS | D10: 6.336634 | E10: 5.218385 | F10: 12.734732 | G10: 12.419154 | H10: 3200 | I10: =H10*0.00689476 -> 22.063232 | J10: Gas-inflow | K10: LOAD
A11: F7289H | B11: 5055.1 | C11: BR 1-BRSA-1045-SPS | D11: 6.324587 | E11: 5.251751 | F11: 12.734732 | G11: 12.426224 | H11: 2800 | I11: =H11*0.00689476 -> 19.305328 | J11: Gas-inflow | K11: UNLOAD
A12: F7289H | B12: 5055.1 | C12: BR 1-BRSA-1045-SPS | D12: 6.404803 | E12: 5.274282 | F12: 12.734732 | G12: 12.431346 | H12: 2400 | I12: =H12*0.00689476 -> 16.547424 | J12: Gas-inflow | K12: UNLOAD
A13: F7289H | B13: 5055.1 | C13: BR 1-BRSA-1045-SPS | D13: 6.45983 | E13: 5.217527 | F13: 12.734732 | G13: 12.425055 | H13: 2000 | I13: =H13*0.00689476 -> 13.78952 | J13: Gas-inflow | K13: UNLOAD
A14: F7289H | B14: 5055.1 | C14: BR 1-BRSA-1045-SPS | D14: 6.467303 | E14: 5.368351 | F14: 12.734732 | G14: 12.429823 | H14: 1600 | I14: =H14*0.00689476 -> 11.031616 | J14: Gas-inflow | K14: UNLOAD
... A44: F7291H | B44: 5055.4 | C44: BR 1-BRSA-1045-SPS | D44: 0.007199763 | E44: 0.001152585 | F44: 6.7768173 | G44: 6.154577 | H44: 1600 | I44: =H44*0.00689476 -> 11.031616 | J44: Gas-inflow | K44: UNLOAD
A45: F7291H | B45: 5055.4 | C45: BR 1-BRSA-1045-SPS | D45: NA | E45: NA | F45: 6.7768173 | G45: 6.2382524 | H45: NA | I45: NA | J45: Gas-inflow | K45: UNLOAD
A46: F7291H | B46: 5055.4 | C46: BR 1-BRSA-1045-SPS | D46: NA | E46: NA | F46: 6.7768173 | G46: 6.2126324 | H46: NA | I46: NA | J46: Gas-inflow | K46: UNLOAD
A47: F7291H | B47: 5055.4 | C47: BR 1-BRSA-1045-SPS | D47: NA | E47: NA | F47: 6.7768173 | G47: 6.2712331 | H47: NA | I47: NA | J47: Gas-inflow | K47: UNLOAD
A48: F7292H | B48: 5055.75 | C48: BR 1-BRSA-1045-SPS | D48: 18.80698 | E48: 16.52088 | F48: 16.220505 | G48: 16.110613 | H48: 400 | I48: =H48*0.00689476 -> 2.757904 | J48: Gas-inflow | K48: LOAD
A49: F7292H | B49: 5055.75 | C49: BR 1-BRSA-1045-SPS | D49: 18.46513 | E49: 16.12039 | F49: 16.220505 | G49: 15.934523 | H49: 800 | I49: =H49*0.00689476 -> 5.515808 | J49: Gas-inflow | K49: LOAD
A50: F7292H | B50: 5055.75 | C50: BR 1-BRSA-1045-SPS | D50: 18.32129 | E50: 15.32188 | F50: 16.220505 | G50: 15.806226 | H50: 1200 | I50: =H50*0.00689476 -> 8.273712 | J50: Gas-inflow | K50: LOAD
A51: F7292H | B51: 5055.75 | C51: BR 1-BRSA-1045-SPS | D51: 18.09193 | E51: 15.4623 | F51: 16.220505 | G51: 15.714923 | H51: 1600 | I51: =H51*0.00689476 -> 11.031616 | J51: Gas-inflow | K51: LOAD
A52: F7292H | B52: 5055.75 | C52: BR 1-BRSA-1045-SPS | D52: 18.05035 | E52: 14.93604 | F52: 16.220505 | G52: 15.665319 | H52: 2000 | I52: =H52*0.00689476 -> 13.78952 | J52: Gas-inflow | K52: LOAD
A53: F7292H | B53: 5055.75 | C53: BR 1-BRSA-1045-SPS | D53: 17.73076 | E53: 15.1899 | F53: 16.220505 | G53: 15.614509 | H53: 2400 | I53: =H53*0.00689476 -> 16.547424 | J53: Gas-inflow | K53: LOAD
A54: F7292H | B54: 5055.75 | C54: BR 1-BRSA-1045-SPS | D54: 17.75853 | E54: 14.80909 | F54: 16.220505 | G54: 15.562698 | H54: 2800 | I54: =H54*0.00689476 -> 19.305328 | J54: Gas-inflow | K54: LOAD
A55: F7292H | B55: 5055.75 | C55: BR 1-BRSA-1045-SPS | D55: 17.64027 | E55: 14.83719 | F55: 16.220505 | G55: 15.525511 | H55: 3200 | I55: =H55*0.00689476 -> 22.063232 | J55: Gas-inflow | K55: LOAD
A56: F7292H | B56: 5055.75 | C56: BR 1-BRSA-1045-SPS | D56: 17.62542 | E56: 14.9767 | F56: 16.220505 | G56: 15.51785 | H56: 2800 | I56: =H56*0.00689476 -> 19.305328 | J56: Gas-inflow | K56: UNLOAD
A57: F7292H | B57: 5055.75 | C57: BR 1-BRSA-1045-SPS | D57: 17.73138 | E57: 14.85457 | F57: 16.220505 | G57: 15.536096 | H57: 2400 | I57: =H57*0.00689476 -> 16.547424 | J57: Gas-inflow | K57: UNLOAD
A58: F7292H | B58: 5055.75 | C58: BR 1-BRSA-1045-SPS | D58: 17.64883 | E58: 15.43191 | F58: 16.220505 | G58: 15.54716 | H58: 2000 | I58: =H58*0.00689476 -> 13.78952 | J58: Gas-inflow | K58: UNLOAD
A59: F7292H | B59: 5055.75 | C59: BR 1-BRSA-1045-SPS | D59: 17.92851 | E59: 15.10476 | F59: 16.220505 | G59: 15.562992 | H59: 1600 | I59: =H59*0.00689476 -> 11.031616 | J59: Gas-inflow | K59: UNLOAD
... A137: F7297H | B137: 5056.95 | C137: BR 1-BRSA-1045-SPS | D137: 110.8613 | E137: 102.239 | F137: 9.6542884 | G137: 9.2223742 | H137: 400 | I137: =H137*0.00689476 -> 2.757904 | J137: Gas-inflow | K137: UNLOAD
H138: 9.6542884 | M138: 8.9655379 | N138: 1600 | O138: =N138*0.00689476 -> 11.031616
H139: 9.6542884 | M139: 9.0021411 | N139: 1200 | O139: =N139*0.00689476 -> 8.273712
H140: 9.6542884 | M140: 9.0918192 | N140: 800 | O140: =N140*0.00689476 -> 5.515808
H141: 9.6542884 | M141: 9.2223742 | N141: 400 | O141: =N141*0.00689476 -> 2.757904
A623: A15 | C623: Morro do Chaves Fm. | D623: 0.2865055 | E623: 0.156377 | F623: 4.17 | G623: 4.0338956 | H623: 700 | I623: 4.826332 | J623: Gas-inflow | K623: LOAD
A624: A15 | C624: Morro do Chaves Fm. | D624: 0.2009538 | E624: 0.09391106 | F624: 4.17 | G624: 3.7929016 | H624: 1200 | I624: 8.273712 | J624: Gas-inflow | K624: LOAD
A625: A15 | C625: Morro do Chaves Fm. | D625: 0.1494197 | E625: 0.06828867 | F625: 4.17 | G625: 3.6126903 | H625: 1700 | I625: 11.721092 | J625: Gas-inflow | K625: LOAD
A626: A15 | C626: Morro do Chaves Fm. | D626: 0.1187036 | E626: 0.0484 | F626: 4.17 | G626: 3.4829902 | H626: 2200 | I626: 15.168472 | J626: Gas-inflow | K626: LOAD
A627: A15 | C627: Morro do Chaves Fm. | D627: 0.09582828 | E627: 0.041 | F627: 4.17 | G627: 3.3673752 | H627: 2700 | I627: 18.615852 | J627: Gas-inflow | K627: LOAD
A628: A15 | C628: Morro do Chaves Fm. | D628: 0.08629194 | E628: 0.0384 | F628: 4.17 | G628: 3.3191642 | H628: 3000 | I628: 20.68428 | J628: Gas-inflow | K628: LOAD
...

Sheet Mineralogy
A2: Sample | B2: Depth (m) | C2: Well / Location | D2: Mineral Bulk Modulus (GPa) | E2: Mineral Shear Modulus (GPa) | F2: Mineral Bulk Density (g/cm³) | G2: Calcite (%) | H2: Quartz (%) | I2: Dolomite (%) | J2: Aragonite (%) | K2: K Feldspar (%) | L2: Albite (%) | M2: Dawsonite (%) | N2: Hematite(%) | O2: Pyrite (%) | P2: Kaolinite (%) | Q2: Illite (%) | R2: Montmorillinite (%) | S2: Vermiculite (%) | T2: Fluorite (%) | U2: Magnesite (%) | V2: Clay Minerals (%) | W2: Observation
A3: F7285V | B3: 5054.2 | C3: BR 1-BRSA-1045-SPS | D3: 54.556 | E3: 46.351 | F3: 2.761 | G3: 4.98 | H3: 46.06 | I3: 48.96
A4: F7286H | B4: 5054.3 | C4: BR 1-BRSA-1045-SPS | D4: 76.228 | E4: 49.342 | F4: 2.867 | G4: 1.45 | H4: 0.15 | I4: 98.4
A5: F7287H | B5: 5054.55 | C5: BR 1-BRSA-1045-SPS | D5: 69.725 | E5: 33.041 | F5: 2.724 | G5: 86 | H5: 3.7 | I5: 10.29
A6: F7288H | B6: 5054.8 | C6: BR 1-BRSA-1045-SPS | D6: 52.717 | E6: 43.953 | F6: 2.735 | G6: 15.34 | H6: 49.88 | I6: 34.77
A7: F7289H | B7: 5055.1 | C7: BR 1-BRSA-1045-SPS | D7: 66.516 | E7: 33.868 | F7: 2.72 | G7: 79.31 | H7: 10.63 | I7: 10.06
A8: F7290V | B8: 5055.2 | C8: BR 1-BRSA-1045-SPS | D8: 56.705 | E8: 42.458 | F8: 2.745 | G8: 25.09 | H8: 38.41 | I8: 36.5
A9: F7291H | B9: 5055.4 | C9: BR 1-BRSA-1045-SPS | D9: 50.909 | E9: 46.986 | F9: 2.746 | G9: 0 | H9: 56.53 | I9: 43.47
A10: F7292H | B10: 5055.75 | C10: BR 1-BRSA-1045-SPS | D10: 59.604 | E10: 37.271 | F10: 2.72 | G10: 55.17 | H10: 28.23 | I10: 16.61
A11: F7293H | B11: 5056.1 | C11: BR 1-BRSA-1045-SPS | D11: 55.318 | E11: 39.11 | F11: 2.714 | G11: 42.3 | H11: 40.15 | I11: 17.55
A12: F7294H | B12: 5056.4 | C12: BR 1-BRSA-1045-SPS | D12: 63.785 | E12: 37.44 | F12: 2.739 | G12: 56.26 | H12: 18.64 | I12: 25.11
A13: F7295V | B13: 5056.5 | C13: BR 1-BRSA-1045-SPS | D13: 67.438 | E13: 36.422 | F13: 2.745 | G13: 63.96 | H13: 10.27 | I13: 25.77
A14: F7296H | B14: 5056.65 | C14: BR 1-BRSA-1045-SPS | D14: 67.289 | E14: 38.024 | F14: 2.757 | G14: 54.46 | H14: 11.49 | I14: 34.04
A15: F7297H | B15: 5056.95 | C15: BR 1-BRSA-1045-SPS | D15: 61.756 | E15: 39.238 | F15: 2.745 | G15: 44.98 | H15: 24.27 | I15: 30.75
A16: F2829V | B16: 5206 | C16: BR 3-BRSA-861-SPS | D16: 67.39 | E16: 34.137 | F16: 2.725 | G16: 78 | H16: 9 | I16: 13 | W16: Perforation data
A17: F2830H | B17: 5206.05 | C17: BR 3-BRSA-861-SPS | D17: 59.534 | E17: 36.616 | F17: 2.714 | G17: 59 | H17: 28 | I17: 13 | W17: Perforation data
A18: F2846H | B18: 5210.05 | C18: BR 3-BRSA-861-SPS | D18: 69.373 | E18: 35.727 | F18: 2.746 | G18: 69 | H18: 6 | I18: 25 | W18: Perforation data
A19: F2852H | B19: 5211.4 | C19: BR 3-BRSA-861-SPS | D19: 62.011 | E19: 41.654 | F19: 2.764 | G19: 32 | H19: 25 | I19: 43 | V19: TR | W19: Perforation data
A20: F2853H | B20: 5211.8 | C20: BR 3-BRSA-861-SPS | D20: 69.28 | E20: 45.92 | F20: 2.8 | G20: 2 | H20: 34 | I20: 56 | U20: C | W20: Perforation data
A21: F2854H | B21: 5212.05 | C21: BR 3-BRSA-861-SPS | D21: 69.373 | E21: 35.727 | F21: 2.746 | G21: 69 | H21: 6 | I21: 25 | W21: Perforation data
A22: F2855V | B22: 5212.15 | C22: BR 3-BRSA-861-SPS | D22: 67.024 | E22: 36.219 | F22: 2.742 | G22: 65 | H22: 11 | I22: 24 | W22: Perforation data
A23: F2857H | B23: 5212.7 | C23: BR 3-BRSA-861-SPS | D23: 65.891 | E23: 37.31 | F23: 2.746 | G23: 58 | H23: 14 | I23: 28 | W23: Perforation data
A24: F2858V | B24: 5212.75 | C24: BR 3-BRSA-861-SPS | D24: 68.921 | E24: 34.243 | F24: 2.732 | G24: 78 | H24: 6 | I24: 16 | M24: TR | W24: Perforation data
A25: F2859H | B25: 5212.9 | C25: BR 3-BRSA-861-SPS | D25: 63.816 | E25: 36.472 | F25: 2.731 | G25: 62 | H25: 18 | I25: 20 | W25: Perforation data
A26: F2868H | B26: 5215.2 | C26: BR 3-BRSA-861-SPS | D26: 67.864 | E26: 37.46 | F26: 2.755 | G26: 58 | H26: 10 | I26: 32 | W26: Perforation data
A27: F2870H | B27: 5215.55 | C27: BR 3-BRSA-861-SPS | D27: 69.222 | E27: 35.227 | F27: 2.742 | G27: 72 | H27: 6 | I27: 22 | W27: Perforation data
A28: F2880H | B28: 5218.25 | C28: BR 3-BRSA-861-SPS | D28: 66.867 | E28: 37.385 | F28: 2.751 | G28: 58 | H28: 12 | I28: 30 | W28: Perforation data
A29: F2889H | B29: 5220.2 | C29: BR 3-BRSA-861-SPS | D29: 65.076 | E29: 37.76 | F29: 2.747 | G29: 55 | H29: 16 | I29: 29 | W29: Perforation data
A30: F2900V | B30: 5220.6 | C30: BR 3-BRSA-861-SPS | D30: 68.045 | E30: 39.939 | F30: 2.775 | G30: 44 | H30: 11 | I30: 45 | W30: Perforation data
A31: F2901H | B31: 5223.5 | C31: BR 3-BRSA-861-SPS | D31: 67.192 | E31: 40.419 | F31: 2.776 | G31: 41 | H31: 13 | I31: 46 | W31: Perforation data
A32: F2908H | B32: 5225.25 | C32: BR 3-BRSA-861-SPS | D32: 65.162 | E32: 43.683 | F32: 2.791 | G32: 23 | H32: 18 | I32: 58 | K32: 1 | W32: Perforation data
A33: F2909V | B33: 5225.35 | C33: BR 3-BRSA-861-SPS | D33: 68.441 | E33: 44.375 | F33: 2.808 | G33: 21 | H33: 10 | I33: 66.5 | K33: 2.5 | W33: Perforation data
A34: F2910H | B34: 5225.7 | C34: BR 3-BRSA-861-SPS | D34: 69.325 | E34: 37.072 | F34: 2.758 | G34: 60 | H34: 5 | I34: 33 | K34: 2 | W34: Perforation data
A35: F2911V | B35: 5225.75 | C35: BR 3-BRSA-861-SPS | D35: 67.07 | E35: 38.017 | F35: 2.757 | G35: 54 | H35: 11 | I35: 34 | K35: 1 | W35: Perforation data
A36: F2913H | B36: 5226.7 | C36: BR 3-BRSA-861-SPS | D36: 71.496193 | E36: 36.348916 | F36: 2.7522439 | G36: 48 | H36: 13 | I36: 36 | K36: 2 | M36: 1 | O36: TR | W36: Perforation data
A37: F2914H | B37: 5227 | C37: BR 3-BRSA-861-SPS | D37: 73.1 | E37: 37.7 | F37: 2.76 | G37: 36 | H37: 13 | I37: 46 | K37: 3 | M37: 2 | O37: TR | W37: Perforation data
A38: F2916H | B38: 5227.35 | C38: BR 3-BRSA-861-SPS | D38: 70.31 | E38: 37.69 | F38: 2.76 | G38: 41 | H38: 18 | I38: 40 | M38: 1 | W38: Perforation data
A39: F2919V | B39: 5228.2 | C39: BR 3-BRSA-861-SPS | D39: 68.702 | E39: 34.048 | F39: 2.729 | G39: 78 | H39: 6 | I39: 15 | K39: 1 | W39: Perforation data
A40: F2928V | B40: 5230.5 | C40: BR 3-BRSA-861-SPS | D40: 69.621 | E40: 34.85 | F40: 2.74 | G40: 74.5 | H40: 5 | I40: 20.5 | W40: Perforation data
A41: F2930H | B41: 5231.3 | C41: BR 3-BRSA-861-SPS | D41: 65.672 | E41: 39.674 | F41: 2.768 | G41: 44 | H41: 16 | I41: 39 | T41: 1 | W41: Perforation data
...

Sheet Velocity
G1: Dry Velocities | T1: Brine Saturated Velocities
H2: Z-Axis | J2: X-Axis | L2: Y-Axis | N2: Elastic properties results | U2: Z-Axis | W2: X-Axis | Y2: Y-Axis | AA2: Fluid Properties for Saturated Measurements
A3: Sample | B3: Depth (m) | C3: Well / Location | D3: P- Frequency (MHz) | E3: S- Frequency (MHz) | F3: Velocity Test Type | G3: Load Pressure (MPa) | H3: VP (Km/s) | I3: VS (Km/s) | J3: VP (Km/s) | K3: VS (Km/s) | L3: VP (Km/s) | M3: VS (Km/s) | N3: Bulk density (g/cm3) | O3: E (GPa) | P3: R. Poisson | Q3: G (GPa) | R3: K (GPa) | S3: Cb (1/GPa) | T3: Load Pressure (MPa) | U3: VP (Km/s) | V3: VS (Km/s) | W3: VP (Km/s) | X3: VS (Km/s) | Y3: VP (Km/s) | Z3: VS (Km/s) | AA3: Fluid Type | AB3: Fluid Density (g/cm³) | AC3: Fluid Bulk Modulus (GPa) | AD3: Fluid VP (Km/s) | AE3: Fluid Temperature (°C) | AF3: Fluid Salinity (ppm) | AG3: Observation
A4: F7289H | B4: 5055.1 | C4: BR 1-BRSA-1045-SPS | D4: 1.2 | E4: 0.9 | F4: Transmission | G4: 0 | H4: 4.729718 | I4: 2.6577791 | N4: 2.363087 | O4: 42.373675 | P4: 0.26925436 | Q4: 16.69235 | R4: 30.606338 | S4: 0.032672971
A5: F7289H | B5: 5055.1 | C5: BR 1-BRSA-1045-SPS | D5: 1.2 | E5: 0.9 | F5: Transmission | G5: 5.5 | H5: 4.8005284 | I5: 2.7259968 | J5: 4.404 | K5: 2.661 | L5: 4.329 | M5: 2.569 | N5: 2.3672509 | O5: 44.401504 | P5: 0.26203882 | Q5: 17.59118 | R5: 31.098562 | S5: 0.032155827 | T5: 5.5 | U5: 5.0009174 | V5: 2.6870915
A6: F7289H | B6: 5055.1 | C6: BR 1-BRSA-1045-SPS | D6: 1.2 | E6: 0.9 | F6: Transmission | G6: 8.3 | H6: 4.9622212 | I6: 2.8134134 | J6: 4.664 | K6: 2.676 | L6: 4.404 | M6: 2.612 | N6: 2.3683688 | O6: 47.358252 | P6: 0.26313348 | Q6: 18.746337 | R6: 33.322743 | S6: 0.030009535 | T6: 8.3 | U6: 5.1327684 | V6: 2.7714306
A7: F7289H | B7: 5055.1 | C7: BR 1-BRSA-1045-SPS | D7: 1.2 | E7: 0.9 | F7: Transmission | G7: 11 | H7: 5.0683403 | I7: 2.8912396 | J7: 4.687 | K7: 2.7 | L7: 4.676 | M7: 2.662 | N7: 2.3691881 | O7: 49.860421 | P7: 0.25880433 | Q7: 19.804675 | R7: 34.453645 | S7: 0.029024505 | T7: 11 | U7: 5.231286 | V7: 2.836201
A8: F7289H | B8: 5055.1 | C8: BR 1-BRSA-1045-SPS | D8: 1.2 | E8: 0.9 | F8: Transmission | G8: 13.8 | H8: 5.1594889 | I8: 2.9619614 | J8: 4.752 | K8: 2.727 | L8: 4.716 | M8: 2.695 | N8: 2.3698948 | O8: 52.154136 | P8: 0.25421189 | Q8: 20.791597 | R8: 35.365241 | S8: 0.028276352 | T8: 13.8 | U8: 5.3025292 | V8: 2.9008782
A9: F7289H | B9: 5055.1 | C9: BR 1-BRSA-1045-SPS | D9: 1.2 | E9: 0.9 | F9: Transmission | G9: 16.5 | H9: 5.2237662 | I9: 3.0056307 | J9: 5.009 | K9: 2.757 | L9: 4.957 | M9: 2.727 | N9: 2.3704595 | O9: 53.645007 | P9: 0.25255129 | Q9: 21.414295 | R9: 36.132072 | S9: 0.027676243 | T9: 16.5 | U9: 5.3493621 | V9: 2.9492863
A10: F7289H | B10: 5055.1 | C10: BR 1-BRSA-1045-SPS | D10: 1.2 | E10: 0.9 | F10: Transmission | G10: 19.3 | H10: 5.2948033 | I10: 3.0422466 | J10: 5.138 | K10: 2.787 | L10: 4.989 | M10: 2.751 | N10: 2.3711827 | O10: 55.022069 | P10: 0.25358299 | Q10: 21.945922 | R10: 37.21474 | S10: 0.026871073 | T10: 19.3 | U10: 5.3916914 | V10: 2.99828
A11: F7289H | B11: 5055.1 | C11: BR 1-BRSA-1045-SPS | D11: 1.2 | E11: 0.9 | F11: Transmission | G11: 22.1 | H11: 5.3362702 | I11: 3.0665033 | J11: 5.173 | K11: 2.803 | L11: 5.049 | M11: 2.776 | N11: 2.371649 | O11: 55.909361 | P11: 0.25347955 | Q11: 22.301665 | R11: 37.799002 | S11: 0.026455725 | T11: 22.1 | U11: 5.4184891 | V11: 3.0281914
A12: F7290V | B12: 5055.2 | C12: BR 1-BRSA-1045-SPS | D12: 1.2 | E12: 0.9 | F12: Transmission | G12: 0 | H12: 3.6789513 | I12: 2.2293616 | N12: 2.3657093 | O12: 28.45011 | P12: 0.20985007 | Q12: 11.757701 | R12: 16.342189 | S12: 0.061191313
A13: F7290V | B13: 5055.2 | C13: BR 1-BRSA-1045-SPS | D13: 1.2 | E13: 0.9 | F13: Transmission | G13: 5.5 | H13: 4.0851414 | I13: 2.3807308 | J13: 3.647 | K13: 2.134 | L13: 3.661 | M13: 2.034 | N13: 2.3768991 | O13: 33.487251 | P13: 0.24284839 | Q13: 13.471977 | R13: 21.703961 | S13: 0.04607454 | T13: 5.5 | U13: 4.3824396 | V13: 2.3913804 | W13: 4.365 | X13: 2.563 | Y13: 4.375 | Z13: 2.566 | AA13: BFW Brine | AB13: 1.201 | AC13: 3.47 | AE13: 22 | AF13: 17027
A14: F7290V | B14: 5055.2 | C14: BR 1-BRSA-1045-SPS | D14: 1.2 | E14: 0.9 | F14: Transmission | G14: 8.3 | H14: 4.4733835 | I14: 2.5863554 | J14: 3.993 | K14: 2.373 | L14: 3.927 | M14: 2.279 | N14: 2.3790219 | O14: 39.750815 | P14: 0.2489389 | Q14: 15.913835 | R14: 26.38854 | S14: 0.037895237 | T14: 8.3 | U14: 4.6106634 | V14: 2.520606 | AA14: BFW Brine | AB14: 1.201 | AC14: 3.47 | AE14: 22 | AF14: 17027
A15: F7290V | B15: 5055.2 | C15: BR 1-BRSA-1045-SPS | D15: 1.2 | E15: 0.9 | F15: Transmission | G15: 11 | H15: 4.6788298 | I15: 2.6978607 | J15: 4.421 | K15: 2.521 | L15: 4.4 | M15: 2.426 | N15: 2.3800109 | O15: 43.340236 | P15: 0.25095961 | Q15: 17.322796 | R15: 29.004824 | S15: 0.034477024 | T15: 11 | U15: 4.7826367 | V15: 2.6341038 | W15: 4.718 | X15: 2.705 | Y15: 4.712 | Z15: 2.77 | AA15: BFW Brine | AB15: 1.201 | AC15: 3.47 | AE15: 22 | AF15: 17027
A16: F7290V | B16: 5055.2 | C16: BR 1-BRSA-1045-SPS | D16: 1.2 | E16: 0.9 | F16: Transmission | G16: 13.8 | H16: 4.7872546 | I16: 2.7730775 | J16: 4.741 | K16: 2.737 | L16: 4.689 | M16: 2.617 | N16: 2.3809705 | O16: 45.68249 | P16: 0.24750342 | Q16: 18.309565 | R16: 30.153868 | S16: 0.033163242 | T16: 13.8 | U16: 4.9121532 | V16: 2.7199679 | AA16: BFW Brine | AB16: 1.201 | AC16: 3.47 | AE16: 22 | AF16: 17027
A17: F7290V | B17: 5055.2 | C17: BR 1-BRSA-1045-SPS | D17: 1.2 | E17: 0.9 | F17: Transmission | G17: 16.5 | H17: 4.8751229 | I17: 2.8275993 | J17: 4.984 | K17: 2.86 | L17: 4.939 | M17: 2.659 | N17: 2.3817921 | O17: 47.475669 | P17: 0.24652649 | Q17: 19.043185 | R17: 31.21672 | S17: 0.032034115 | T17: 16.5 | U17: 5.0047106 | V17: 2.7722672 | W17: 4.939 | X17: 2.8905 | Y17: 4.901 | Z17: 2.815 | AA17: BFW Brine | AB17: 1.201 | AC17: 3.47 | AE17: 22 | AF17: 17027
A18: F7290V | B18: 5055.2 | C18: BR 1-BRSA-1045-SPS | D18: 1.2 | E18: 0.9 | F18: Transmission | G18: 19.3 | H18: 4.926797 | I18: 2.8682447 | J18: 5.004 | K18: 2.885 | L18: 5.024 | M18: 2.756 | N18: 2.3823491 | O18: 48.749288 | P18: 0.24365665 | Q18: 19.599175 | R18: 31.695308 | S18: 0.031550411 | T18: 19.3 | U18: 5.0591837 | V18: 2.8124208 | AA18: BFW Brine | AB18: 1.201 | AC18: 3.47 | AE18: 22 | AF18: 17027
A19: F7290H | B19: 5055.2 | C19: BR 1-BRSA-1045-SPS | D19: 1.2 | E19: 0.9 | F19: Transmission | G19: 22.1 | H19: 4.9563479 | I19: 2.8837491 | J19: 5.057 | K19: 2.902 | L19: 5.084 | M19: 2.865 | N19: 2.3825987 | O19: 49.300993 | P19: 0.24411297 | Q19: 19.813712 | R19: 32.11117 | S19: 0.031141811 | T19: 22.1 | U19: 5.0764505 | V19: 2.8441272 | W19: 5.133 | X19: 2.889 | Y19: 5.105 | Z19: 2.965 | AA19: BFW Brine | AB19: 1.201 | AC19: 3.47 | AE19: 22 | AF19: 17027
A20: F7291H | B20: 5055.4 | C20: BR 1-BRSA-1045-SPS | D20: 1.2 | E20: 0.9 | F20: Transmission | G20: 2.8 | H20: 5.4651523 | I20: 3.0910985 | N20: 2.4987941 | O20: 60.396383 | P20: 0.26480849 | Q20: 23.875703 | R20: 42.799436 | S20: 0.023364794
A21: F7291H | B21: 5055.4 | C21: BR 1-BRSA-1045-SPS | D21: 1.2 | E21: 0.9 | F21: Transmission | G21: 5.5 | H21: 5.5745129 | I21: 3.1796837 | J21: 5.887 | K21: 3.513 | L21: 5.814 | M21: 3.435 | N21: 2.4758013 | O21: 63.022456 | P21: 0.25887235 | Q21: 25.031313 | R21: 43.560922 | S21: 0.022956355 | T21: 5.5 | U21: 5.6248672 | V21: 3.0863288 | AA21: BFW Brine | AB21: 1.201 | AC21: 3.47 | AE21: 22 | AF21: 17027
A22: F7291H | B22: 5055.4 | C22: BR 1-BRSA-1045-SPS | D22: 1.2 | E22: 0.9 | F22: Transmission | G22: 8.3 | H22: 5.7005924 | I22: 3.2587542 | N22: 2.5095111 | O22: 67.013032 | P22: 0.25729429 | Q22: 26.6497 | R22: 46.01803 | S22: 0.021730613 | T22: 8.3 | U22: 5.7783843 | V22: 3.2231278 | AA22: BFW Brine | AB22: 1.201 | AC22: 3.47 | AE22: 22 | AF22: 17027
A23: F7291H | B23: 5055.4 | C23: BR 1-BRSA-1045-SPS | D23: 1.2 | E23: 0.9 | F23: Transmission | G23: 11 | H23: 5.8005479 | I23: 3.3269957 | J23: 5.961 | K23: 3.557 | L23: 5.97 | M23: 3.5055 | N23: 2.511397 | O23: 69.76667 | P23: 0.2548683 | Q23: 27.798403 | R23: 47.434822 | S23: 0.021081559 | T23: 11 | U23: 5.9073661 | V23: 3.3109305 | AA23: BFW Brine | AB23: 1.201 | AC23: 3.47 | AE23: 22 | AF23: 17027
A24: F7291H | B24: 5055.4 | C24: BR 1-BRSA-1045-SPS | D24: 1.2 | E24: 0.9 | F24: Transmission | G24: 13.8 | H24: 5.8909293 | I24: 3.3897019 | N24: 2.513983 | O24: 72.359512 | P24: 0.25250735 | Q24: 28.885863 | R24: 48.728391 | S24: 0.020521917 | T24: 13.8 | U24: 6.0147727 | V24: 3.3722545 | AA24: BFW Brine | AB24: 1.201 | AC24: 3.47 | AE24: 22 | AF24: 17027
A25: F7291H | B25: 5055.4 | C25: BR 1-BRSA-1045-SPS | D25: 1.2 | E25: 0.9 | F25: Transmission | G25: 16.5 | H25: 5.9572313 | I25: 3.4320674 | J25: 6.037 | K25: 3.589 | L25: 5.979 | M25: 3.5275 | N25: 2.515102 | O25: 74.158564 | P25: 0.25159582 | Q25: 29.625604 | R25: 49.756654 | S25: 0.020097814 | T25: 16.5 | U25: 6.0769231 | V25: 3.4097208 | AA25: BFW Brine | AB25: 1.201 | AC25: 3.47 | AE25: 22 | AF25: 17027
A26: F7291H | B26: 5055.4 | C26: BR 1-BRSA-1045-SPS | D26: 1.2 | E26: 0.9 | F26: Transmission | G26: 19.3 | H26: 6.0045377 | I26: 3.4625984 | N26: 2.5159773 | O26: 75.467546 | P26: 0.2508904 | Q26: 30.165531 | R26: 50.491528 | S26: 0.019805303 | T26: 19.3 | U26: 6.1261574 | V26: 3.4331892 | AA26: BFW Brine | AB26: 1.201 | AC26: 3.47 | AE26: 22 | AF26: 17027
A27: F7291H | B27: 5055.4 | C27: BR 1-BRSA-1045-SPS | D27: 1.2 | E27: 0.9 | F27: Transmission | G27: 22.1 | H27: 6.0387906 | I27: 3.4836981 | J27: 6.075 | K27: 3.609 | L27: 6.027 | M27: 3.548 | N27: 2.5167261 | O27: 76.395171 | P27: 0.25060144 | Q27: 30.543372 | R27: 51.052936 | S27: 0.019587512 | T27: 22.1 | U27: 6.1475029 | V27: 3.4480343 | AA27: BFW Brine | AB27: 1.201 | AC27: 3.47 | AE27: 22 | AF27: 17027
A28: F7292H | B28: 5055.75 | C28: BR 1-BRSA-1045-SPS | D28: 1.2 | E28: 0.9 | F28: Transmission | G28: 0 | H28: 4.985889 | I28: 2.6483791 | N28: 2.2966033 | O28: 41.993323 | P28: 0.30347879 | Q28: 16.108173 | R28: 35.613902 | S28: 0.028078923
A29: F7292H | B29: 5055.75 | C29: BR 1-BRSA-1045-SPS | D29: 1.2 | E29: 0.9 | F29: Transmission | G29: 5.5 | H29: 5.0766284 | I29: 2.7461339 | J29: 4.623 | K29: 2.51 | L29: 4.551 | M29: 2.487 | N29: 2.3044541 | O29: 44.946764 | P29: 0.29317396 | Q29: 17.378468 | R29: 36.21946 | S29: 0.027609468 | T29: 5.5 | U29: 5.1406402 | V29: 2.7370976 | W29: 5.179 | X29: 3.015 | Y29: 5.158 | Z29: 3.0735 | AA29: BFW Brine | AB29: 1.201 | AC29: 3.47 | AE29: 22 | AF29: 17027
A30: F7292H | B30: 5055.75 | C30: BR 1-BRSA-1045-SPS | D30: 1.2 | E30: 0.9 | F30: Transmission | G30: 8.3 | H30: 5.2216749 | I30: 2.8703425 | J30: 4.692 | K30: 2.544 | L30: 4.703 | M30: 2.55 | N30: 2.3079711 | O30: 48.811506 | P30: 0.28349565 | Q30: 19.015065 | R30: 37.575463 | S30: 0.026613112 | T30: 8.3 | U30: 5.2736318 | V30: 2.8514744 | AA30: BFW Brine | AB30: 1.201 | AC30: 3.47 | AE30: 22 | AF30: 17027
A31: F7292H | B31: 5055.75 | C31: BR 1-BRSA-1045-SPS | D31: 1.2 | E31: 0.9 | F31: Transmission | G31: 11 | H31: 5.3106212 | I31: 2.9658729 | J31: 4.835 | K31: 2.621 | L31: 4.769 | M31: 2.608 | N31: 2.3104739 | O31: 51.759264 | P31: 0.27336215 | Q31: 20.323858 | R31: 38.063121 | S31: 0.026272149 | T31: 11 | U31: 5.3698075 | V31: 2.9286994 | W31: 5.186 | X31: 3.0365 | Y31: 5.236 | Z31: 3.119 | AA31: BFW Brine | AB31: 1.201 | AC31: 3.47 | AE31: 22 | AF31: 17027
A32: F7292H | B32: 5055.75 | C32: BR 1-BRSA-1045-SPS | D32: 1.2 | E32: 0.9 | F32: Transmission | G32: 13.8 | H32: 5.3861789 | I32: 3.0417394 | J32: 4.885 | K32: 2.676 | L32: 4.805 | M32: 2.634 | N32: 2.3118337 | O32: 54.152703 | P32: 0.2658713 | Q32: 21.389498 | R32: 38.549099 | S32: 0.025940944 | T32: 13.8 | U32: 5.4358974 | V32: 2.9938654 | AA32: BFW Brine | AB32: 1.201 | AC32: 3.47 | AE32: 22 | AF32: 17027
A33: F7292H | B33: 5055.75 | C33: BR 1-BRSA-1045-SPS | D33: 1.2 | E33: 0.9 | F33: Transmission | G33: 16.5 | H33: 5.4247697 | I33: 3.0977826 | J33: 4.988 | K33: 2.695 | L33: 4.975 | M33: 2.669 | N33: 2.3132266 | O33: 55.853614 | P33: 0.2580597 | Q33: 22.198316 | R33: 38.476168 | S33: 0.025990114 | T33: 16.5 | U33: 5.4695562 | V33: 3.0540749 | W33: 5.332 | X33: 3.121 | Y33: 5.28 | Z33: 3.167 | AA33: BFW Brine | AB33: 1.201 | AC33: 3.47 | AE33: 22 | AF33: 17027
A34: F7292H | B34: 5055.75 | C34: BR 1-BRSA-1045-SPS | D34: 1.2 | E34: 0.9 | F34: Transmission | G34: 19.3 | H34: 5.4414784 | I34: 3.1398644 | J34: 5.075 | K34: 2.722 | L34: 4.982 | M34: 2.701 | N34: 2.3146468 | O34: 57.068122 | P34: 0.25042329 | Q34: 22.819521 | R34: 38.109941 | S34: 0.026239872 | T34: 19.3 | U34: 5.492228 | V34: 3.1042382 | AA34: BFW Brine | AB34: 1.201 | AC34: 3.47 | AE34: 22 | AF34: 17027
A35: F7292H | B35: 5055.75 | C35: BR 1-BRSA-1045-SPS | D35: 1.2 | E35: 0.9 | F35: Transmission | G35: 22.1 | H35: 5.4526749 | I35: 3.1624038 | J35: 5.123 | K35: 2.751 | L35: 5.116 | M35: 2.718 | N35: 2.3156662 | O35: 57.737392 | P35: 0.24656973 | Q35: 23.158509 | R35: 37.970597 | S35: 0.026336167 | T35: 22.1 | U35: 5.4979253 | V35: 3.1134714 | W35: 5.408 | X35: 3.149 | Y35: 5.431 | Z35: 3.2075 | AA35: BFW Brine | AB35: 1.201 | AC35: 3.47 | AE35: 22 | AF35: 17027
A36: F7293H | B36: 5056.1 | C36: BR 1-BRSA-1045-SPS | D36: 1.2 | E36: 0.9 | F36: Transmission | G36: 5.5 | H36: 5.5348571 | I36: 2.9966391 | J36: 4.696 | K36: 2.46 | L36: 4.661 | M36: 2.626 | N36: 2.3811605 | O36: 55.280451 | P36: 0.29265921 | Q36: 21.382454 | R36: 44.436064 | S36: 0.022504243 | T36: 5.5 | U36: 5.5730725 | V36: 2.677653 | W36: 5.291 | X36: 2.9335 | Y36: 5.212 | Z36: 2.9 | AA36: BFW Brine | AB36: 1.201 | AC36: 3.47 | AE36: 22 | AF36: 17027
A37: F7293H | B37: 5056.1 | C37: BR 1-BRSA-1045-SPS | D37: 1.2 | E37: 0.9 | F37: Transmission | G37: 8.3 | H37: 5.6313953 | I37: 3.1086666 | J37: 4.713 | K37: 2.565 | L37: 4.772 | M37: 2.82 | N37: 2.3839127 | O37: 59.015802 | P37: 0.28085417 | Q37: 23.037674 | R37: 44.883203 | S37: 0.02228005 | T37: 8.3 | U37: 5.6643275 | V37: 2.7994266 | AA37: BFW Brine | AB37: 1.201 | AC37: 3.47 | AE37: 22 | AF37: 17027
A38: F7293H | B38: 5056.1 | C38: BR 1-BRSA-1045-SPS | D38: 1.2 | E38: 0.9 | F38: Transmission | G38: 11 | H38: 5.6842723 | I38: 3.1843491 | J38: 4.754 | K38: 2.612 | L38: 4.979 | M38: 2.844 | N38: 2.38582 | O38: 61.512563 | P38: 0.27131981 | Q38: 24.192403 | R38: 44.831578 | S38: 0.022305706 | T38: 11 | U38: 5.7381517 | V38: 2.9020043 | W38: 5.336 | X38: 2.9495 | Y38: 5.277 | Z38: 2.911 | AA38: BFW Brine | AB38: 1.201 | AC38: 3.47 | AE38: 22 | AF38: 17027
A39: F7293H | B39: 5056.1 | C39: BR 1-BRSA-1045-SPS | D39: 1.2 | E39: 0.9 | F39: Transmission | G39: 13.8 | H39: 5.7245863 | I39: 3.2495543 | J39: 4.986 | K39: 2.638 | L39: 5.019 | M39: 2.864 | N39: 2.3875837 | O39: 63.649649 | P39: 0.26229193 | Q39: 25.211937 | R39: 44.627323 | S39: 0.022407797 | T39: 13.8 | U39: 5.8139256 | V39: 2.9849069 | AA39: BFW Brine | AB39: 1.201 | AC39: 3.47 | AE39: 22 | AF39: 17027
A40: F7293H | B40: 5056.1 | C40: BR 1-BRSA-1045-SPS | D40: 1.2 | E40: 0.9 | F40: Transmission | G40: 16.5 | H40: 5.7654762 | I40: 3.2958901 | J40: 5.039 | K40: 2.675 | L40: 5.025 | M40: 2.901 | N40: 2.3891115 | O40: 65.259751 | P40: 0.25728445 | Q40: 25.95266 | R40: 44.81223 | S40: 0.022315337 | T40: 16.5 | U40: 5.8561064 | V40: 3.0441177 | W40: 5.359 | X40: 2.954 | Y40: 5.306 | Z40: 2.9365 | AA40: BFW Brine | AB40: 1.201 | AC40: 3.47 | AE40: 22 | AF40: 17027
...

Sheet DIA Parameters
A1: Digital Image Analysis (DIA) Parameters - values from pore system image & measurements
A2: Sample | B2: Depth (m) | C2: Well/ Location | D2: Thin Section | E2: Image Resolution (µm) | F2: Perimeter over Area (mm^-1) | G2: DomSize (microns) | H2: Mean Specific Surface Area (microns^-1) (Tiab and Donaldson, 2004) | I2: Specific Pore Surface Area (mm^-1) | J2: Permeability (Kozeny) (mD) | K2: Permeability (Kozeny-Carman) (mD) | L2: DIA Porosity (%) | M2: Microcroporosity (Anselmetti et al., 1998)(%) | N2: Macro-mesoporosity (Anselmetti et al., 1998)(%) | O2: Pore radius | P2: Pore radius Microporosity (Anselmetti et al., 1998) | Q2: Pore radius Macro-mesoporosity (Anselmetti et al., 1998) | R2: Pore area | S2: Pore area Microporosity (Anselmetti et al., 1998) | T2: Pore area Macro-mesoporosity (Anselmetti et al., 1998) | U2: Pore perimeter | V2: Pore perimeter Microporosity (Anselmetti et al., 1998) | W2: Pore perimeter Macro-mesoporosity (Anselmetti et al., 1998) | X2: Mean Gamma | Y2: Mean Gamma Microporosity (Anselmetti et al., 1998) | Z2: Mean Gamma Macro-mesoporosity (Anselmetti et al., 1998) | AA2: Mean Fps (microns^-1) (equal to gamma^2) | AB2: Mean Fps Microporosity (Anselmetti et al., 1998) (microns^-1) | AC2: Mean Fps Macro-mesoporosity (Anselmetti et al., 1998) (microns^-1) | AD2: Specific pore surface (microns^-1) | AE2: Specific Pore surface Microporosity (microns^-1) | AF2: Specific Pore surface Macro-mesoporosity (microns^-1) | AG2: Mean Aspect Ratio | AH2: Median Aspect Ratio
A3: - | C3: BR 1-BRSA-1045-SPS | D3: 4587-1 | F3: 112.774 | G3: 132.202 | H3: 0.033 | I3: 12.382 | J3: 50.05 | K3: 20.02 | L3: 4.447 | M3: 0.152 | N3: 4.295 | O3: 15.878 | P3: 6.999 | Q3: 38.776 | R3: 3351.123 | S3: 170.519 | T3: 11876.084 | U3: 321.473 | V3: 95.374 | W3: 946.24 | X3: 2.37 | Y3: 2.116 | Z3: 3.084 | AA3: 5.664 | AB3: 4.522 | AC3: 9.686 | AD3: 0.678 | AE3: 0.828 | AF3: 0.304 | AG3: 0.537 | AH3: 0.529
A4: F7285V | B4: 5054.2 | C4: BR 1-BRSA-1045-SPS | D4: 7285V | F4: 314.076 | G4: 94.413 | H4: 0.021 | I4: 49.921 | J4: 19.726 | K4: 7.89 | L4: 2.365 | M4: 0.315 | N4: 2.05 | O4: 8.092 | P4: 6.22 | Q4: 23.57 | R4: 653.635 | S4: 132.852 | T4: 4970.429 | U4: 137.575 | V4: 83.194 | W4: 597.942 | X4: 2.177 | Y4: 2.071 | Z4: 3.06 | AA4: 4.78 | AB4: 4.315 | AC4: 10.993 | AD4: 0.853 | AE4: 0.893 | AF4: 0.406 | AG4: 0.498 | AH4: 0.483
A5: F7286H | B5: 5054.3 | C5: BR 1-BRSA-1045-SPS | D5: 7187-1 | F5: 107.842 | G5: 123.827 | H5: 0.085 | I5: 11.712 | J5: 97.975 | K5: 39.19 | L5: 9.558 | M5: 0.394 | N5: 9.164 | O5: 13.072 | P5: 6.686 | Q5: 37.589 | R5: 2610.063 | S5: 154.457 | T5: 11959.584 | U5: 260.746 | V5: 85.229 | W5: 943.841 | X5: 2.201 | Y5: 1.977 | Z5: 3.079 | AA5: 4.861 | AB5: 3.919 | AC5: 9.633 | AD5: 0.701 | AE5: 0.801 | AF5: 0.315 | AG5: 0.547 | AH5: 0.54
A6: F7287H | B6: 5054.55 | C6: BR 1-BRSA-1045-SPS | D6: 71880-1 | F6: 145.831 | G6: 116.925 | H6: 0.048 | I6: 17.705 | J6: 65.414 | K6: 26.166 | L6: 6.14 | M6: 0.402 | N6: 5.738 | O6: 12.094 | P6: 6.744 | Q6: 31.982 | R6: 1773.199 | S6: 156.932 | T6: 7885.533 | U6: 226.25 | V6: 85.926 | W6: 751.334 | X6: 2.19 | Y6: 1.973 | Z6: 3.033 | AA6: 4.808 | AB6: 3.9 | AC6: 9.289 | AD6: 0.698 | AE6: 0.792 | AF6: 0.337 | AG6: 0.535 | AH6: 0.525
A7: F7288H | B7: 5054.8 | C7: BR 1-BRSA-1045-SPS | D7: 7189-1 | F7: 129.403 | G7: 120.74 | H7: 0.073 | I7: 12.373 | J7: 88.317 | K7: 35.327 | L7: 8.585 | M7: 0.51 | N7: 8.075 | O7: 12.993 | P7: 6.709 | Q7: 32.14 | R7: 2043.974 | S7: 155.78 | T7: 8095.766 | U7: 251.611 | V7: 85.962 | W7: 775.536 | X7: 2.224 | Y7: 1.989 | Z7: 2.992 | AA7: 4.976 | AB7: 3.974 | AC7: 9.147 | AD7: 0.685 | AE7: 0.807 | AF7: 0.325 | AG7: 0.547 | AH7: 0.54
A8: F7289H | B8: 5055.1 | C8: BR 1-BRSA-1045-SPS | D8: 7190-1 | F8: 181.594 | G8: 128.528 | H8: 0.007 | I8: 21.514 | J8: 9.221 | K8: 3.688 | L8: 0.959 | M8: 0.127 | N8: 0.832 | O8: 11.213 | P8: 6.652 | Q8: 29.545 | R8: 945.372 | S8: 153.252 | T8: 4171.548 | U8: 204.247 | V8: 89.201 | W8: 657.49 | X8: 2.309 | Y8: 2.073 | Z8: 3.211 | AA8: 5.367 | AB8: 4.313 | AC8: 10.521 | AD8: 0.746 | AE8: 0.844 | AF8: 0.353 | AG8: 0.513 | AH8: 0.496
A9: F7290V | B9: 5055.2 | C9: BR 1-BRSA-1045-SPS | D9: 7290V | F9: 213.203 | G9: 137.071 | H9: 0.017 | I9: 21.497 | J9: 14.372 | K9: 5.749 | L9: 1.965 | M9: 0.395 | N9: 1.57 | O9: 9.511 | P9: 6.385 | Q9: 32.076 | R9: 825.68 | S9: 139.528 | T9: 6516.327 | U9: 164.99 | V9: 86.336 | W9: 817.871 | X9: 2.258 | Y9: 2.081 | Z9: 3.658 | AA9: 5.151 | AB9: 4.366 | AC9: 14.413 | AD9: 0.805 | AE9: 0.868 | AF9: 0.406 | AG9: 0.533 | AH9: 0.525
A10: F7291H | B10: 5055.4 | C10: BR 1-BRSA-1045-SPS | D10: 7191-1 | F10: 175.41 | G10: 147.969 | H10: 0.008 | I10: 24.517 | J10: 10.925 | K10: 4.37 | L10: 1.094 | M10: 0.147 | N10: 0.947 | O10: 11.137 | P10: 6.536 | Q10: 32.327 | R10: 1072.897 | S10: 146.934 | T10: 6000.827 | U10: 210.381 | V10: 88.907 | W10: 760.161 | X10: 2.29 | Y10: 2.081 | Z10: 3.243 | AA10: 5.299 | AB10: 4.347 | AC10: 11 | AD10: 0.762 | AE10: 0.85 | AF10: 0.355 | AG10: 0.487 | AH10: 0.475
A11: F7292H | B11: 5055.75 | C11: BR 1-BRSA-1045-SPS | D11: 7192-1 | F11: 202.175 | G11: 110.382 | H11: 0.03 | I11: 20.15 | J11: 25.754 | K11: 10.302 | L11: 3.389 | M11: 0.265 | N11: 3.125 | O11: 10.78 | P11: 6.492 | Q11: 30.58 | R11: 1520.488 | S11: 144.968 | T11: 7369.548 | U11: 250.55 | V11: 96.86 | W11: 982.075 | X11: 2.556 | Y11: 2.294 | Z11: 3.784 | AA11: 6.566 | AB11: 5.289 | AC11: 15.324 | AD11: 0.865 | AE11: 0.946 | AF11: 0.414 | AG11: 0.527 | AH11: 0.513
A12: F7293H | B12: 5056.1 | C12: BR 1-BRSA-1045-SPS | D12: 7193-2 | F12: 124.273 | G12: 128.302 | H12: 0.023 | I12: 15.3 | J12: 46.693 | K12: 18.677 | L12: 3.551 | M12: 0.305 | N12: 3.245 | O12: 12.912 | P12: 6.762 | Q12: 31.929 | R12: 1390.88 | S12: 158.206 | T12: 5200.235 | U12: 206.309 | V12: 80.726 | W12: 594.714 | X12: 2.048 | Y12: 1.859 | Z12: 2.625 | AA12: 4.2 | AB12: 3.463 | AC12: 6.91 | AD12: 0.634 | AE12: 0.75 | AF12: 0.273 | AG12: 0.549 | AH12: 0.538
A13: F7294H | B13: 5056.4 | C13: BR 1-BRSA-1045-SPS | D13: 7194-1 | F13: 110.487 | G13: 124.645 | H13: 0.026 | I13: 12.422 | J13: 54.143 | K13: 21.657 | L13: 3.946 | M13: 0.259 | N13: 3.687 | O13: 13.381 | P13: 6.688 | Q13: 32.509 | R13: 1734.011 | S13: 154.393 | T13: 6309.4 | U13: 215.385 | V13: 76.881 | W13: 618.447 | X13: 1.989 | Y13: 1.78 | Z13: 2.6 | AA13: 3.973 | AB13: 3.181 | AC13: 6.836 | AD13: 0.606 | AE13: 0.72 | AF13: 0.277 | AG13: 0.537 | AH13: 0.525
A14: F7295V | B14: 5056.5 | C14: BR 1-BRSA-1045-SPS | D14: 7295V | F14: 152.491 | G14: 114.653 | H14: 0.068 | I14: 11.34 | J14: 97.661 | K14: 39.064 | L14: 8.881 | M14: 0.748 | N14: 8.133 | O14: 11.967 | P14: 6.71 | Q14: 30.532 | R14: 1359.238 | S14: 155.707 | T14: 5615.724 | U14: 232.905 | V14: 84.822 | W14: 764.56 | X14: 2.216 | Y14: 1.952 | Z14: 3.177 | AA14: 4.922 | AB14: 3.814 | AC14: 10.124 | AD14: 0.687 | AE14: 0.786 | AF14: 0.339 | AG14: 0.56 | AH14: 0.554
A15: F7296H | B15: 5056.65 | C15: BR 1-BRSA-1045-SPS | D15: 7391-1 | F15: 93.514 | G15: 125.238 | H15: 0.049 | I15: 9.293 | J15: 76.102 | K15: 30.441 | L15: 6.428 | M15: 0.256 | N15: 6.172 | O15: 15.353 | P15: 6.844 | Q15: 41.718 | R15: 3121.321 | S15: 162.506 | T15: 12601.93 | U15: 296.088 | V15: 86.603 | W15: 951.203 | X15: 2.198 | Y15: 1.961 | Z15: 2.938 | AA15: 4.84 | AB15: 3.856 | AC15: 8.683 | AD15: 0.659 | AE15: 0.78 | AF15: 0.284 | AG15: 0.549 | AH15: 0.547
A16: F7297H | B16: 5056.95 | C16: BR 1-BRSA-1045-SPS | D16: 7196-1 | F16: 99.961 | G16: 117.857 | H16: 0.072 | I16: 9.309 | J16: 74.413 | K16: 29.765 | L16: 7.501 | M16: 0.21 | N16: 7.291 | O16: 13.085 | P16: 6.514 | Q16: 42.74 | R16: 3786.613 | S16: 146.035 | T16: 21451.257 | U16: 263.816 | V16: 82.062 | W16: 1096.972 | X16: 2.172 | Y16: 1.955 | Z16: 3.121 | AA16: 4.732 | AB16: 3.835 | AC16: 9.832 | AD16: 0.717 | AE16: 0.811 | AF16: 0.316 | AG16: 0.538 | AH16: 0.531
A17: F2855V | B17: 5212.15 | C17: BR 3-BRSA-861-SPS | D17: F2855V | E17: 0.44 | F17: 1010.8866 | G17: 20.666667 | H17: 20.666667 | I17: 123.26544 | J17: 0.84045314 | K17: 0.33618125 | L17: 1.690924 | M17: 1.5129726 | N17: 0.17795139 | O17: 1.8683293 | P17: 1.8357088 | Q17: 15.079638 | R17: 16.719697 | S17: 14.997069 | T17: 714.384 | U17: 25.524833 | V17: 24.151511 | W17: 581.72048 | X17: 1.9784209 | Y17: 1.9681462 | Z17: 6.1396493 | AA17: 3.9141491 | AB17: 3.8735995 | AC17: 37.695293 | AD17: 3.1922311 | AE17: 3.1975531 | AF17: 1.0367947 | AG17: 0.56450124 | AH17: 0.55862241
A18: F2859H | B18: 5212.9 | C18: BR 3-BRSA-861-SPS | D18: F2859H | E18: 0.44 | F18: 584.53448 | G18: 24.583333 | H18: 0.28064794 | I18: 56.085554 | J18: 6.196604 | K18: 2.4786416 | L18: 9.2577643 | M18: 4.3019869 | N18: 4.9557774 | O18: 2.4849661 | P18: 2.1793917 | Q18: 20.490349 | R18: 47.708855 | S18: 22.54606 | T18: 1530.3782 | U18: 37.239127 | V18: 28.469356 | W18: 553.98102 | X18: 1.9351619 | Y18: 1.8975195 | Z18: 4.1531667 | AA18: 3.7448516 | AB18: 3.6005803 | AC18: 17.248794 | AD18: 2.7508393 | AE18: 2.7880856 | AF18: 0.55616798 | AG18: 0.58248401 | AH18: 0.57166927
A19: F2870H | B19: 5215.55 | C19: BR 3-BRSA-861-SPS | D19: F2870H | E19: 0.44 | F19: 1853.2575 | G19: 21.5 | H19: 0.0067608835 | I19: 516.10132 | J19: 0.034433236 | K19: 0.013773294 | L19: 0.14578511 | M19: 0.14578511 | N19: 0 | O19: 1.4650408 | P19: 1.4650408 | Q19: 0 | R19: 8.3607543 | S19: 8.3607543 | T19: 0 | U19: 24.192036 | V19: 24.192036 | W19: 0 | X19: 2.4449432 | Y19: 2.4449432 | Z19: 0 | AA19: 5.9777473 | AB19: 5.9777473 | AC19: 0 | AD19: 4.6308071 | AE19: 4.6308071 | AF19: 0 | AG19: 0.5145642 | AH19: 0.51235449
A20: F2880H | B20: 5218.25 | C20: BR 3-BRSA-861-SPS | D20: F2880H | E20: 0.44 | F20: 1188.8626 | G20: 20.35 | H20: 0.25083159 | I20: 59.720677 | J20: 1.4080975 | K20: 0.56323899 | L20: 5.3897087 | M20: 3.1617477 | N20: 2.227961 | O20: 1.8256223 | P20: 1.7185821 | Q20: 22.719874 | R20: 22.055993 | S20: 13.004921 | T20: 1788.8253 | U20: 38.832475 | V20: 33.413747 | W20: 1096.5684 | X20: 2.708195 | Y20: 2.6826127 | Z20: 7.7018576 | AA20: 7.33432 | AB20: 7.1964108 | AC20: 59.318611 | AD20: 4.4030672 | AE20: 4.4207435 | AF20: 0.95264954 | AG20: 0.56164489 | AH20: 0.55329397
A21: F2908H | B21: 5225.25 | C21: BR 3-BRSA-861-SPS | D21: F2908H | E21: 0.44 | F21: 2524.9354 | G21: 19.25 | H21: 0.1397066 | I21: 201.88818 | J21: 0.56655249 | K21: 0.226621 | L21: 2.7435378 | M21: 2.6145833 | N21: 0.12895448 | O21: 1.5292824 | P21: 1.5193808 | Q21: 12.836849 | R21: 9.6359615 | S21: 9.1910837 | T21: 517.6864 | U21: 31.503387 | V21: 30.750815 | W21: 890.9406 | X21: 2.8104741 | Y21: 2.8032625 | Z21: 11.046137 | AA21: 7.8987647 | AB21: 7.8582806 | AC21: 122.01715 | AD21: 4.9524993 | AE21: 4.9549172 | AF21: 2.1912509 | AG21: 0.55375988 | AH21: 0.54168644
A22: F2910H | B22: 5225.7 | C22: BR 3-BRSA-861-SPS | D22: F2910H | E22: 0.44 | F22: 1882.6555 | G22: 21.25 | H22: 0.25985671 | I22: 92.552072 | J22: 1.1775129 | K22: 0.47100516 | L22: 5.2056327 | M22: 4.0176987 | N22: 1.187934 | O22: 1.5912107 | P22: 1.5479972 | Q22: 18.941435 | R22: 12.980098 | S22: 10.04297 | T22: 1192.2372 | U22: 34.259592 | V22: 30.362894 | W22: 1598.7841 | X22: 2.7185755 | Y22: 2.6929312 | Z22: 13.014781 | AA22: 7.3906528 | AB22: 7.2518782 | AC22: 169.38453 | AD22: 4.7319805 | AE22: 4.7392727 | AF22: 1.804166 | AG22: 0.54711932 | AH22: 0.53385916
A23: F2913H | B23: 5226.7 | C23: BR 3-BRSA-861-SPS | D23: F2913H | E23: 0.44 | F23: 1860.9473 | G23: 18.5 | H23: 0.018313876 | I23: 358.21104 | J23: 0.086084002 | K23: 0.034433601 | L23: 0.38387346 | M23: 0.38387346 | N23: 0 | O23: 1.2106866 | P23: 1.2106866 | Q23: 0 | R23: 4.8613754 | S23: 4.8613754 | T23: 0 | U23: 17.17994 | V23: 17.17994 | W23: 0 | X23: 2.2130799 | Y23: 2.2130799 | Z23: 0 | AA23: 4.8977227 | AB23: 4.8977227 | AC23: 0 | AD23: 4.7524969 | AE23: 4.7524969 | AF23: 0 | AG23: 0.53800785 | AH23: 0.52978509
A24: F2919V | B24: 5228.2 | C24: BR 3-BRSA-861-SPS | D24: F2919V | E24: 0.44 | F24: 401.63183 | G24: 22.458333 | H24: 1.6963073 | I24: 19.538922 | J24: 12.502419 | K24: 5.0009675 | L24: 32.018567 | M24: 7.9175829 | N24: 24.100984 | O24: 2.2206717 | P24: 1.9032557 | Q24: 29.576155 | R24: 67.01679 | S24: 16.764269 | T24: 4397.8704 | U24: 40.869271 | V24: 31.708443 | W24: 830.36606 | X24: 2.3501646 | Y24: 2.3246002 | Z24: 4.5533518 | AA24: 5.5232735 | AB24: 5.4037659 | AC24: 20.733012 | AD24: 3.601579 | AE24: 3.6368359 | AF24: 0.56307803 | AG24: 0.56384436 | AH24: 0.55498353
A25: F2934V | B25: 5232.05 | C25: BR 3-BRSA-861-SPS | D25: F2934V | E25: 0.44 | F25: 565.66629 | G25: 26.206897 | H25: 2.0363721 | I25: 63.536869 | J25: 30.446947 | K25: 12.178779 | L25: 43.17636 | M25: 20.459346 | N25: 22.717014 | O25: 2.9029506 | P25: 2.4636035 | Q25: 18.963527 | R25: 64.101719 | S25: 31.205863 | T25: 1266.628 | U25: 45.331878 | V25: 35.357989 | W25: 409.93294 | X25: 2.0496652 | Y25: 2.0126127 | Z25: 3.4041399 | AA25: 4.2011273 | AB25: 4.0506097 | AC25: 11.588168 | AD25: 2.6800331 | AE25: 2.739705 | AF25: 0.49869487 | AG25: 0.52507578 | AH25: 0.51618061
A26: F2935H | B26: 5232.25 | C26: BR 3-BRSA-861-SPS | D26: F2935H | E26: 0.44 | F26: 632.9495 | G26: 22.857143 | H26: 0.53832078 | I26: 42.052666 | J26: 8.1623395 | K26: 3.2649358 | L26: 14.998794 | M26: 6.8530093 | N26: 8.1457851 | O26: 2.2283323 | P26: 1.9895476 | Q26: 23.151841 | R26: 42.462979 | S26: 19.62292 | T26: 2043.8231 | U26: 36.62502 | V26: 28.855509 | W26: 717.42844 | X26: 2.0296508 | Y26: 1.9966227 | Z26: 4.9237456 | AA26: 4.1194825 | AB26: 3.986502 | AC26: 24.243271 | AD26: 3.0507729 | AE26: 3.0786138 | AF26: 0.6112148 | AG26: 0.56881026 | AH26: 0.55887976

Sheet microCT
A1: Whole sample | J1: Subvolume | T1: Cumulative porosity | Y1: Shape factor | AC1: Non-Archie pore size classification
A2: Sample | B2: Dimensions (pixels) | C2: mm/pixel | D2: Volume (cm³) | E2: Dry weight (g) | F2: Density (g/cm³) | G2: Laboratory Porosity (%) | H2: Porosity estimation by GeoDict (without crop) (%) | I2: Treshold | J2: Dimensions (pixels) | K2: mm/pixel | L2: Porosity estimation by GeoDict (subvolume) (%) | M2: Porosity estimation using Anselmetti approach (%) | N2: Predominance | O2: Aspect ratio variation | P2: Median pore aspect ratio | Q2: Mean pore aspect ratio | R2: Concentration of the pore size diameter (μm) | S2: Gamma | T2: Dominant pore size (µm) | U2: Average pore size diameter (µm) | V2: Accumulated porosity (%) | W2: Average pore surface area ( µm²) | X2: Median perimeter (μm) | Y2: Specific pore surface (1/µm) | Z2: Frequency distribution (1/µm) | AA2: Larger distribution (1/µm) | AB2: Approached pore shape | AC2: Mesopores (%) | AD2: Macropores (%)
A3: COQ-9 | B3: 1069 X 1042 X 1468 | C3: 3 | D3: 17.84 | E3: 32.122 | F3: 2.694 | G3: 18.638 | H3: 19.6585 | I3: 30.5 | J3: 700 X 700 X 800 | K3: 2 | L3: 18.4859 | M3: 18.0558 | N3: macro-mesopores | O3: 0.11 - 0.94 | P3: 0.55924 | Q3: 0.55714 | R3: 43.97 - 753.20 | S3: 1 - 1.47 | T3: 318.0269 | U3: 113 | V3: 9 | W3: 9 | X3: 283 | Y3: 0.0479 | Z3: 1 - 1.2 | AA3: 1 | AB3: Sphere or subspherical | AC3: 48.6 | AD3: 51.4
A4: COQ-2 | B4: 738 X 743 X 870 | C4: 3 | E4: 28.437 | F4: 2.705 | G4: 25.32 | H4: 28.3534 | I4: 36.5 | J4: 295 X 743 X 870 | K4: 3 | L4: 28.07 | M4: 27.81 | N4: macro-mesopores | O4: 0.14 - 0.93 | P4: 0.56433 | Q4: 0.56292 | R4: 900 | S4: 1 - 1.4 | T4: 12.78 | W4: 8 | X4: 28.4 | Y4: 0.02 - 0.08 | Z4: 1 | AB4: Spherical

Sheet Electrical Resistivity
G1: Rock Electical Resistivity Results | J1: Fluid Properties for Saturated Resistivity Measurements
A2: Sample | B2: Well / Location | C2: Depth (m) | D2: Well/ Location | E2: Min. Phase Frequency (Hz) to determine m coefficient | F2: Confining Pressure (psi) | G2: Resitivity (ohm-m) - Ro | H2: Cementation Factor (m coefficient) | I2: Formation Factor | J2: Fluid Type | K2: Fluid Density (g/cm³) | L2: Fluid Resistivity (Ohm-m) - Measured with the sample | M2: Fluid Temperature (°C) | N2: Fluid Salinity (ppm) | O2: Observation
A3: F7289H | B3: BR 1-BRSA-1045-SPS | C3: 5055.1 | D3: BR 1-BRSA-1045-SPS | E3: 10000 | F3: 400 | G3: 6.8172187 | H3: 2.0514184 | I3: 70.217 | J3: BFW Brine | K3: 1.201 | L3: 0.097087379 | M3: 22 | N3: 17027
A4: F7289H | B4: BR 1-BRSA-1045-SPS | C4: 5055.1 | D4: BR 1-BRSA-1045-SPS | E4: 10000 | F4: 800 | G4: 6.8727936 | H4: 2.0549 | I4: 70.79 | J4: BFW Brine | K4: 1.201 | L4: 0.097087379 | M4: 22 | N4: 17027
A5: F7289H | B5: BR 1-BRSA-1045-SPS | C5: 5055.1 | D5: BR 1-BRSA-1045-SPS | E5: 10000 | F5: 1200 | G5: 6.9945164 | H5: 2.0601202 | I5: 72.044 | J5: BFW Brine | K5: 1.201 | L5: 0.097087379 | M5: 22 | N5: 17027
A6: F7289H | B6: BR 1-BRSA-1045-SPS | C6: 5055.1 | D6: BR 1-BRSA-1045-SPS | E6: 10000 | F6: 1600 | G6: 7.0820133 | H6: 2.0637068 | I6: 72.945 | J6: BFW Brine | K6: 1.201 | L6: 0.097087379 | M6: 22 | N6: 17027
A7: F7289H | B7: BR 1-BRSA-1045-SPS | C7: 5055.1 | D7: BR 1-BRSA-1045-SPS | E7: 10000 | F7: 2000 | G7: 7.1743501 | H7: 2.0678614 | I7: 73.896 | J7: BFW Brine | K7: 1.201 | L7: 0.097087379 | M7: 22 | N7: 17027
A8: F7289H | B8: BR 1-BRSA-1045-SPS | C8: 5055.1 | D8: BR 1-BRSA-1045-SPS | E8: 10000 | F8: 2400 | G8: 7.22921 | H8: 2.0699 | I8: 74.461 | J8: BFW Brine | K8: 1.201 | L8: 0.097087379 | M8: 22 | N8: 17027
